Workbook

Sheet 原始行情
A1: 模拟股票月度行情（数据已完整提供，无需外部检索）
A2: 日期 | B2: 股票代码 | C2: 股票名称 | D2: 行业 | E2: 收盘价 | F2: 当月现金分红 | G2: 基准指数收盘
A3: 45322 | B3: S001 | C3: 华曜科技 | D3: 科技 | E3: 18 | F3: 0 | G3: 1000
A4: 45322 | B4: S002 | C4: 云帆软件 | D4: 科技 | E4: 21.15 | F4: 0 | G4: 1000
A5: 45322 | B5: S003 | C5: 江海银行 | D5: 金融 | E5: 24.3 | F5: 0 | G5: 1000
A6: 45322 | B6: S004 | C6: 安信证券 | D6: 金融 | E6: 27.45 | F6: 0 | G6: 1000
A7: 45322 | B7: S005 | C7: 远岭医药 | D7: 医药 | E7: 30.6 | F7: 0 | G7: 1000
A8: 45322 | B8: S006 | C8: 康泽生物 | D8: 医药 | E8: 33.75 | F8: 0 | G8: 1000
A9: 45322 | B9: S007 | C9: 东辰消费 | D9: 消费 | E9: 36.9 | F9: 0 | G9: 1000
A10: 45322 | B10: S008 | C10: 新禾食品 | D10: 消费 | E10: 40.05 | F10: 0 | G10: 1000
A11: 45322 | B11: S009 | C11: 瀚源能源 | D11: 能源 | E11: 43.2 | F11: 0 | G11: 1000
A12: 45322 | B12: S010 | C12: 启明电力 | D12: 能源 | E12: 46.35 | F12: 0 | G12: 1000
A13: 45322 | B13: S011 | C13: 联港工业 | D13: 工业 | E13: 49.5 | F13: 0 | G13: 1000
A14: 45322 | B14: S012 | C14: 锐虎机械 | D14: 工业 | E14: 52.65 | F14: 0 | G14: 1000
... A290: 46022 | B290: S012 | C290: 锐虎机械 | D290: 工业 | E290: 71.78 | F290: 0 | G290: 1140.83

Sheet 参数设置
A1: 股票组合分析参数
A2: 参数 | B2: 数值 | C2: 说明 | D2: 目标组合权重
A3: 组合规模 | B3: 10000000 | C3: 用于仓位、市值与风险金额计算 | D3: 股票代码 | E3: 目标权重
A4: 无风险年利率 | B4: 0.022 | C4: CAPM 与夏普比率使用 | D4: S001 | E4: 0.1
A5: 单股权重上限 | B5: 0.15 | C5: 任何单只股票不得超过该上限 | D5: S002 | E5: 0.09
A6: 行业权重上限 | B6: 0.35 | C6: 同一行业合计权重不得超过该上限 | D6: S003 | E6: 0.1
A7: VaR 单尾置信系数 | B7: 1.645 | C7: 95% 单尾正态近似 | D7: S004 | E7: 0.08
A8: 年化月份数 | B8: 12 | C8: 月度数据年化系数 | D8: S005 | E8: 0.09
D9: S006 | E9: 0.07
D10: S007 | E10: 0.09
D11: S008 | E11: 0.08
D12: S009 | E12: 0.08
D13: S010 | E13: 0.07
D14: S011 | E14: 0.08
D15: S012 | E15: 0.07
D16: 合计 | E16: =SUM(E4:E15) -> 1
A20: 压力情景：行业价格冲击
A21: 行业 | B21: 温和回撤 | C21: 流动性冲击 | D21: 增长反弹
A22: 科技 | B22: -0.08 | C22: -0.18 | D22: 0.16
A23: 金融 | B23: -0.05 | C23: -0.22 | D23: 0.07
A24: 医药 | B24: -0.03 | C24: -0.1 | D24: 0.09
A25: 消费 | B25: -0.04 | C25: -0.14 | D25: 0.11
A26: 能源 | B26: -0.06 | C26: -0.17 | D26: 0.05
A27: 工业 | B27: -0.05 | C27: -0.19 | D27: 0.1

Sheet 组合分析
A1: 股票组合收益与风险分析
A2: 蓝色单元格为公式结果；所有收益率、风险指标与贡献值均应保持公式联动。
A5: 股票代码 | B5: 股票名称 | C5: 行业 | D5: 最新价 | E5: 期初价 | F5: 累计收益率 | G5: 年化收益率 | H5: 年化波动率 | I5: Beta | J5: CAPM期望收益 | K5: Alpha | L5: 仅基于负月收益的年化下行波动率 | M5: 目标权重 | N5: 加权收益贡献 | O5: 加权Beta贡献 | P5: 月度VaR贡献 | Q5: 配置判断
A6: S001 | B6: 华曜科技 | C6: 科技 | D6: ='原始行情'!E279 -> 20.5 | E6: ='原始行情'!E3 -> 18 | F6: =PRODUCT(1+'月度收益'!B$2:B$24)-1 -> 0.14884907 | G6: =(1+F6)^(12/23)-1 -> 0.075081907 | H6: =STDEV.S('月度收益'!B$2:B$24)*SQRT(12) -> 0.14569563 | I6: =SLOPE('月度收益'!B$2:B$24,'月度收益'!$N$2:$N$24) -> 1.2767811 | J6: ='参数设置'!$B$4+I6*('组合分析'!$B$28-'参数设置'!$B$4) -> 0.084766729 | K6: =G6-J6 -> -0.0096848226 | L6: =SQRT(SUMPRODUCT(('月度收益'!B$2:B$24<0)*'月度收益'!B$2:B$24*'月度收益'!B$2:B$24)/COUNTIF('月度收益'!B$2:B$24,"<0"))*SQRT(12) -> 0.12326338 | M6: ='参数设置'!E4 -> 0.1 | N6: =M6*G6 -> 0.0075081907 | O6: =M6*I6 -> 0.12767811 | P6: =M6*'参数设置'!$B$3*'参数设置'!$B$7*H6/SQRT(12) -> 69186.57 | Q6: =IF(AND(K6>1.5%,I6<1.15),"增配观察",IF(K6>-1%,"维持","降低暴露")) -> 维持
A7: S002 | B7: 云帆软件 | C7: 科技 | D7: ='原始行情'!E280 -> 25.96 | E7: ='原始行情'!E4 -> 21.15 | F7: =PRODUCT(1+'月度收益'!C$2:C$24)-1 -> 0.23776348 | G7: =(1+F7)^(12/23)-1 -> 0.11771916 | H7: =STDEV.S('月度收益'!C$2:C$24)*SQRT(12) -> 0.12055472 | I7: =SLOPE('月度收益'!C$2:C$24,'月度收益'!$N$2:$N$24) -> 0.90538075 | J7: ='参数设置'!$B$4+I7*('组合分析'!$B$28-'参数设置'!$B$4) -> 0.066508637 | K7: =G7-J7 -> 0.051210522 | L7: =SQRT(SUMPRODUCT(('月度收益'!C$2:C$24<0)*'月度收益'!C$2:C$24*'月度收益'!C$2:C$24)/COUNTIF('月度收益'!C$2:C$24,"<0"))*SQRT(12) -> 0.13914637 | M7: ='参数设置'!E5 -> 0.09 | N7: =M7*G7 -> 0.010594724 | O7: =M7*I7 -> 0.081484267 | P7: =M7*'参数设置'!$B$3*'参数设置'!$B$7*H7/SQRT(12) -> 51523.104 | Q7: =IF(AND(K7>1.5%,I7<1.15),"增配观察",IF(K7>-1%,"维持","降低暴露")) -> 增配观察
A8: S003 | B8: 江海银行 | C8: 金融 | D8: ='原始行情'!E281 -> 30.48 | E8: ='原始行情'!E5 -> 24.3 | F8: =PRODUCT(1+'月度收益'!D$2:D$24)-1 -> 0.26423379 | G8: =(1+F8)^(12/23)-1 -> 0.13012722 | H8: =STDEV.S('月度收益'!D$2:D$24)*SQRT(12) -> 0.13469918 | I8: =SLOPE('月度收益'!D$2:D$24,'月度收益'!$N$2:$N$24) -> 1.0547851 | J8: ='参数设置'!$B$4+I8*('组合分析'!$B$28-'参数设置'!$B$4) -> 0.073853373 | K8: =G8-J8 -> 0.056273847 | L8: =SQRT(SUMPRODUCT(('月度收益'!D$2:D$24<0)*'月度收益'!D$2:D$24*'月度收益'!D$2:D$24)/COUNTIF('月度收益'!D$2:D$24,"<0"))*SQRT(12) -> 0.12461113 | M8: ='参数设置'!E6 -> 0.1 | N8: =M8*G8 -> 0.013012722 | O8: =M8*I8 -> 0.10547851 | P8: =M8*'参数设置'!$B$3*'参数设置'!$B$7*H8/SQRT(12) -> 63964.678 | Q8: =IF(AND(K8>1.5%,I8<1.15),"增配观察",IF(K8>-1%,"维持","降低暴露")) -> 增配观察
A9: S004 | B9: 安信证券 | C9: 金融 | D9: ='原始行情'!E282 -> 35.75 | E9: ='原始行情'!E6 -> 27.45 | F9: =PRODUCT(1+'月度收益'!E$2:E$24)-1 -> 0.31229325 | G9: =(1+F9)^(12/23)-1 -> 0.15234185 | H9: =STDEV.S('月度收益'!E$2:E$24)*SQRT(12) -> 0.14692906 | I9: =SLOPE('月度收益'!E$2:E$24,'月度收益'!$N$2:$N$24) -> 1.1958996 | J9: ='参数设置'!$B$4+I9*('组合分析'!$B$28-'参数设置'!$B$4) -> 0.08079058 | K9: =G9-J9 -> 0.071551273 | L9: =SQRT(SUMPRODUCT(('月度收益'!E$2:E$24<0)*'月度收益'!E$2:E$24*'月度收益'!E$2:E$24)/COUNTIF('月度收益'!E$2:E$24,"<0"))*SQRT(12) -> 0.12604139 | M9: ='参数设置'!E7 -> 0.08 | N9: =M9*G9 -> 0.012187348 | O9: =M9*I9 -> 0.095671965 | P9: =M9*'参数设置'!$B$3*'参数设置'!$B$7*H9/SQRT(12) -> 55817.83 | Q9: =IF(AND(K9>1.5%,I9<1.15),"增配观察",IF(K9>-1%,"维持","降低暴露")) -> 维持
A10: S005 | B10: 远岭医药 | C10: 医药 | D10: ='原始行情'!E283 -> 37.66 | E10: ='原始行情'!E7 -> 30.6 | F10: =PRODUCT(1+'月度收益'!F$2:F$24)-1 -> 0.24003148 | G10: =(1+F10)^(12/23)-1 -> 0.11878723 | H10: =STDEV.S('月度收益'!F$2:F$24)*SQRT(12) -> 0.15235003 | I10: =SLOPE('月度收益'!F$2:F$24,'月度收益'!$N$2:$N$24) -> 1.247718 | J10: ='参数设置'!$B$4+I10*('组合分析'!$B$28-'参数设置'!$B$4) -> 0.083337979 | K10: =G10-J10 -> 0.03544925 | L10: =SQRT(SUMPRODUCT(('月度收益'!F$2:F$24<0)*'月度收益'!F$2:F$24*'月度收益'!F$2:F$24)/COUNTIF('月度收益'!F$2:F$24,"<0"))*SQRT(12) -> 0.15505312 | M10: ='参数设置'!E8 -> 0.09 | N10: =M10*G10 -> 0.010690851 | O10: =M10*I10 -> 0.11229462 | P10: =M10*'参数设置'!$B$3*'参数设置'!$B$7*H10/SQRT(12) -> 65111.893 | Q10: =IF(AND(K10>1.5%,I10<1.15),"增配观察",IF(K10>-1%,"维持","降低暴露")) -> 维持
A11: S006 | B11: 康泽生物 | C11: 医药 | D11: ='原始行情'!E284 -> 42.79 | E11: ='原始行情'!E8 -> 33.75 | F11: =PRODUCT(1+'月度收益'!G$2:G$24)-1 -> 0.27701519 | G11: =(1+F11)^(12/23)-1 -> 0.13607406 | H11: =STDEV.S('月度收益'!G$2:G$24)*SQRT(12) -> 0.14193508 | I11: =SLOPE('月度收益'!G$2:G$24,'月度收益'!$N$2:$N$24) -> 1.1467518 | J11: ='参数设置'!$B$4+I11*('组合分析'!$B$28-'参数设置'!$B$4) -> 0.078374469 | K11: =G11-J11 -> 0.057699586 | L11: =SQRT(SUMPRODUCT(('月度收益'!G$2:G$24<0)*'月度收益'!G$2:G$24*'月度收益'!G$2:G$24)/COUNTIF('月度收益'!G$2:G$24,"<0"))*SQRT(12) -> 0.12260052 | M11: ='参数设置'!E9 -> 0.07 | N11: =M11*G11 -> 0.0095251839 | O11: =M11*I11 -> 0.080272625 | P11: =M11*'参数设置'!$B$3*'参数设置'!$B$7*H11/SQRT(12) -> 47180.558 | Q11: =IF(AND(K11>1.5%,I11<1.15),"增配观察",IF(K11>-1%,"维持","降低暴露")) -> 增配观察
A12: S007 | B12: 东辰消费 | C12: 消费 | D12: ='原始行情'!E285 -> 45.63 | E12: ='原始行情'!E9 -> 36.9 | F12: =PRODUCT(1+'月度收益'!H$2:H$24)-1 -> 0.24561171 | G12: =(1+F12)^(12/23)-1 -> 0.12141117 | H12: =STDEV.S('月度收益'!H$2:H$24)*SQRT(12) -> 0.1034025 | I12: =SLOPE('月度收益'!H$2:H$24,'月度收益'!$N$2:$N$24) -> 0.70968735 | J12: ='参数设置'!$B$4+I12*('组合分析'!$B$28-'参数设置'!$B$4) -> 0.056888324 | K12: =G12-J12 -> 0.064522849 | L12: =SQRT(SUMPRODUCT(('月度收益'!H$2:H$24<0)*'月度收益'!H$2:H$24*'月度收益'!H$2:H$24)/COUNTIF('月度收益'!H$2:H$24,"<0"))*SQRT(12) -> 0.10764622 | M12: ='参数设置'!E10 -> 0.09 | N12: =M12*G12 -> 0.010927006 | O12: =M12*I12 -> 0.063871862 | P12: =M12*'参数设置'!$B$3*'参数设置'!$B$7*H12/SQRT(12) -> 44192.524 | Q12: =IF(AND(K12>1.5%,I12<1.15),"增配观察",IF(K12>-1%,"维持","降低暴露")) -> 增配观察
A13: S008 | B13: 新禾食品 | C13: 消费 | D13: ='原始行情'!E286 -> 50.69 | E13: ='原始行情'!E10 -> 40.05 | F13: =PRODUCT(1+'月度收益'!I$2:I$24)-1 -> 0.27460418 | G13: =(1+F13)^(12/23)-1 -> 0.13495447 | H13: =STDEV.S('月度收益'!I$2:I$24)*SQRT(12) -> 0.098938327 | I13: =SLOPE('月度收益'!I$2:I$24,'月度收益'!$N$2:$N$24) -> 0.66356556 | J13: ='参数设置'!$B$4+I13*('组合分析'!$B$28-'参数设置'!$B$4) -> 0.05462097 | K13: =G13-J13 -> 0.080333496 | L13: =SQRT(SUMPRODUCT(('月度收益'!I$2:I$24<0)*'月度收益'!I$2:I$24*'月度收益'!I$2:I$24)/COUNTIF('月度收益'!I$2:I$24,"<0"))*SQRT(12) -> 0.07033019 | M13: ='参数设置'!E11 -> 0.08 | N13: =M13*G13 -> 0.010796357 | O13: =M13*I13 -> 0.053085245 | P13: =M13*'参数设置'!$B$3*'参数设置'!$B$7*H13/SQRT(12) -> 37586.322 | Q13: =IF(AND(K13>1.5%,I13<1.15),"增配观察",IF(K13>-1%,"维持","降低暴露")) -> 增配观察
A14: S009 | B14: 瀚源能源 | C14: 能源 | D14: ='原始行情'!E287 -> 52.34 | E14: ='原始行情'!E11 -> 43.2 | F14: =PRODUCT(1+'月度收益'!J$2:J$24)-1 -> 0.22060848 | G14: =(1+F14)^(12/23)-1 -> 0.10960981 | H14: =STDEV.S('月度收益'!J$2:J$24)*SQRT(12) -> 0.12796348 | I14: =SLOPE('月度收益'!J$2:J$24,'月度收益'!$N$2:$N$24) -> 0.98913482 | J14: ='参数设置'!$B$4+I14*('组合分析'!$B$28-'参数设置'!$B$4) -> 0.070625998 | K14: =G14-J14 -> 0.038983808 | L14: =SQRT(SUMPRODUCT(('月度收益'!J$2:J$24<0)*'月度收益'!J$2:J$24*'月度收益'!J$2:J$24)/COUNTIF('月度收益'!J$2:J$24,"<0"))*SQRT(12) -> 0.11711826 | M14: ='参数设置'!E12 -> 0.08 | N14: =M14*G14 -> 0.0087687845 | O14: =M14*I14 -> 0.079130786 | P14: =M14*'参数设置'!$B$3*'参数设置'!$B$7*H14/SQRT(12) -> 48612.877 | Q14: =IF(AND(K14>1.5%,I14<1.15),"增配观察",IF(K14>-1%,"维持","降低暴露")) -> 增配观察
A15: S010 | B15: 启明电力 | C15: 能源 | D15: ='原始行情'!E288 -> 57.74 | E15: ='原始行情'!E12 -> 46.35 | F15: =PRODUCT(1+'月度收益'!K$2:K$24)-1 -> 0.2549891 | G15: =(1+F15)^(12/23)-1 -> 0.12580798 | H15: =STDEV.S('月度收益'!K$2:K$24)*SQRT(12) -> 0.12549312 | I15: =SLOPE('月度收益'!K$2:K$24,'月度收益'!$N$2:$N$24) -> 0.98342826 | J15: ='参数设置'!$B$4+I15*('组合分析'!$B$28-'参数设置'!$B$4) -> 0.070345463 | K15: =G15-J15 -> 0.055462521 | L15: =SQRT(SUMPRODUCT(('月度收益'!K$2:K$24<0)*'月度收益'!K$2:K$24*'月度收益'!K$2:K$24)/COUNTIF('月度收益'!K$2:K$24,"<0"))*SQRT(12) -> 0.10227088 | M15: ='参数设置'!E13 -> 0.07 | N15: =M15*G15 -> 0.0088065588 | O15: =M15*I15 -> 0.068839978 | P15: =M15*'参数设置'!$B$3*'参数设置'!$B$7*H15/SQRT(12) -> 41715.096 | Q15: =IF(AND(K15>1.5%,I15<1.15),"增配观察",IF(K15>-1%,"维持","降低暴露")) -> 增配观察
A16: S011 | B16: 联港工业 | C16: 工业 | D16: ='原始行情'!E289 -> 65.33 | E16: ='原始行情'!E13 -> 49.5 | F16: =PRODUCT(1+'月度收益'!L$2:L$24)-1 -> 0.32951072 | G16: =(1+F16)^(12/23)-1 -> 0.16020538 | H16: =STDEV.S('月度收益'!L$2:L$24)*SQRT(12) -> 0.14278901 | I16: =SLOPE('月度收益'!L$2:L$24,'月度收益'!$N$2:$N$24) -> 1.1553403 | J16: ='参数设置'!$B$4+I16*('组合分析'!$B$28-'参数设置'!$B$4) -> 0.07879668 | K16: =G16-J16 -> 0.081408701 | L16: =SQRT(SUMPRODUCT(('月度收益'!L$2:L$24<0)*'月度收益'!L$2:L$24*'月度收益'!L$2:L$24)/COUNTIF('月度收益'!L$2:L$24,"<0"))*SQRT(12) -> 0.13919227 | M16: ='参数设置'!E14 -> 0.08 | N16: =M16*G16 -> 0.012816431 | O16: =M16*I16 -> 0.092427223 | P16: =M16*'参数设置'!$B$3*'参数设置'!$B$7*H16/SQRT(12) -> 54245.04 | Q16: =IF(AND(K16>1.5%,I16<1.15),"增配观察",IF(K16>-1%,"维持","降低暴露")) -> 维持
A17: S012 | B17: 锐虎机械 | C17: 工业 | D17: ='原始行情'!E290 -> 71.78 | E17: ='原始行情'!E14 -> 52.65 | F17: =PRODUCT(1+'月度收益'!M$2:M$24)-1 -> 0.3734785 | G17: =(1+F17)^(12/23)-1 -> 0.18006807 | H17: =STDEV.S('月度收益'!M$2:M$24)*SQRT(12) -> 0.1632535 | I17: =SLOPE('月度收益'!M$2:M$24,'月度收益'!$N$2:$N$24) -> 1.3806785 | J17: ='参数设置'!$B$4+I17*('组合分析'!$B$28-'参数设置'!$B$4) -> 0.089874336 | K17: =G17-J17 -> 0.090193738 | L17: =SQRT(SUMPRODUCT(('月度收益'!M$2:M$24<0)*'月度收益'!M$2:M$24*'月度收益'!M$2:M$24)/COUNTIF('月度收益'!M$2:M$24,"<0"))*SQRT(12) -> 0.13042851 | M17: ='参数设置'!E15 -> 0.07 | N17: =M17*G17 -> 0.012604765 | O17: =M17*I17 -> 0.096647495 | P17: =M17*'参数设置'!$B$3*'参数设置'!$B$7*H17/SQRT(12) -> 54267 | Q17: =IF(AND(K17>1.5%,I17<1.15),"增配观察",IF(K17>-1%,"维持","降低暴露")) -> 维持
A20: 组合汇总
A21: 权重合计 | B21: =SUM(M6:M17) -> 1
A22: 组合年化收益率 | B22: ='月度收益'!P24^(12/23)-1 -> 0.13062684
A23: 组合年化波动率 | B23: =STDEV.S('月度收益'!O2:O24)*SQRT(12) -> 0.11455607
A24: 组合Beta | B24: =SUM(O6:O17) -> 1.0568827
A25: 95%单月VaR | B25: ='参数设置'!B3*'参数设置'!B7*STDEV.S('月度收益'!O2:O24) -> 543993.09
A26: 夏普比率 | B26: =(B22-'参数设置'!B4)/B23 -> 0.94824164
A27: 最大回撤 | B27: =MIN('月度收益'!R2:R24) -> -0.12933142
A28: 基准年化收益率 | B28: =('原始行情'!G279/'原始行情'!G3)^(12/23)-1 -> 0.071160132

Sheet 月度收益
A1: 月份 | B1: S001 | C1: S002 | D1: S003 | E1: S004 | F1: S005 | G1: S006 | H1: S007 | I1: S008 | J1: S009 | K1: S010 | L1: S011 | M1: S012 | N1: 基准月收益率 | O1: 组合月收益率 | P1: 组合累计净值 | Q1: 基准累计净值 | R1: 组合回撤
A2: 45351 | B2: =('原始行情'!E15+'原始行情'!F15)/'原始行情'!E3-1 -> 0.042222222 | C2: =('原始行情'!E16+'原始行情'!F16)/'原始行情'!E4-1 -> 0.037825059 | D2: =('原始行情'!E17+'原始行情'!F17)/'原始行情'!E5-1 -> 0.025514403 | E2: =('原始行情'!E18+'原始行情'!F18)/'原始行情'!E6-1 -> 0.014571949 | F2: =('原始行情'!E19+'原始行情'!F19)/'原始行情'!E7-1 -> 0.0081699346 | G2: =('原始行情'!E20+'原始行情'!F20)/'原始行情'!E8-1 -> 0.020740741 | H2: =('原始行情'!E21+'原始行情'!F21)/'原始行情'!E9-1 -> 0.023848238 | I2: =('原始行情'!E22+'原始行情'!F22)/'原始行情'!E10-1 -> 0.050686642 | J2: =('原始行情'!E23+'原始行情'!F23)/'原始行情'!E11-1 -> 0.065046296 | K2: =('原始行情'!E24+'原始行情'!F24)/'原始行情'!E12-1 -> 0.069255663 | L2: =('原始行情'!E25+'原始行情'!F25)/'原始行情'!E13-1 -> 0.057979798 | M2: =('原始行情'!E26+'原始行情'!F26)/'原始行情'!E14-1 -> 0.038746439 | N2: ='原始行情'!G15/'原始行情'!G3-1 -> 0.02931 | O2: =SUMPRODUCT(B2:M2,'参数设置'!$E$4:$E$15) -> 0.037134327 | P2: =1+O2 -> 1.0371343 | Q2: =1+N2 -> 1.02931 | R2: =P2/MAX($P$2:P2)-1 -> 0
A3: 45382 | B3: =('原始行情'!E27+'原始行情'!F27)/'原始行情'!E15-1 -> 0.030916844 | C3: =('原始行情'!E28+'原始行情'!F28)/'原始行情'!E16-1 -> 0.0095671982 | D3: =('原始行情'!E29+'原始行情'!F29)/'原始行情'!E17-1 -> -0.003611557 | E3: =('原始行情'!E30+'原始行情'!F30)/'原始行情'!E18-1 -> 0.012926391 | F3: =('原始行情'!E31+'原始行情'!F31)/'原始行情'!E19-1 -> 0.044408428 | G3: =('原始行情'!E32+'原始行情'!F32)/'原始行情'!E20-1 -> 0.07053701 | H3: =('原始行情'!E33+'原始行情'!F33)/'原始行情'!E21-1 -> 0.047908947 | I3: =('原始行情'!E34+'原始行情'!F34)/'原始行情'!E22-1 -> 0.027091255 | J3: =('原始行情'!E35+'原始行情'!F35)/'原始行情'!E23-1 -> 0.013040643 | K3: =('原始行情'!E36+'原始行情'!F36)/'原始行情'!E24-1 -> 0.028853914 | L3: =('原始行情'!E37+'原始行情'!F37)/'原始行情'!E25-1 -> 0.052892878 | M3: =('原始行情'!E38+'原始行情'!F38)/'原始行情'!E26-1 -> 0.058328762 | N3: ='原始行情'!G27/'原始行情'!G15-1 -> 0.026716927 | O3: =SUMPRODUCT(B3:M3,'参数设置'!$E$4:$E$15) -> 0.031416612 | P3: =P2*(1+O3) -> 1.0697176 | Q3: =Q2*(1+N3) -> 1.05681 | R3: =P3/MAX($P$2:P3)-1 -> 0
A4: 45412 | B4: =('原始行情'!E39+'原始行情'!F39)/'原始行情'!E27-1 -> 0.0041365047 | C4: =('原始行情'!E40+'原始行情'!F40)/'原始行情'!E28-1 -> -0.019855596 | D4: =('原始行情'!E41+'原始行情'!F41)/'原始行情'!E29-1 -> 0.0028191704 | E4: =('原始行情'!E42+'原始行情'!F42)/'原始行情'!E30-1 -> 0.042892591 | F4: =('原始行情'!E43+'原始行情'!F43)/'原始行情'!E31-1 -> 0.037243948 | G4: =('原始行情'!E44+'原始行情'!F44)/'原始行情'!E32-1 -> 0.011117137 | H4: =('原始行情'!E45+'原始行情'!F45)/'原始行情'!E33-1 -> 0.0093457944 | I4: =('原始行情'!E46+'原始行情'!F46)/'原始行情'!E34-1 -> 0.043729755 | J4: =('原始行情'!E47+'原始行情'!F47)/'原始行情'!E35-1 -> 0.039476507 | K4: =('原始行情'!E48+'原始行情'!F48)/'原始行情'!E36-1 -> 0.0027456364 | L4: =('原始行情'!E49+'原始行情'!F49)/'原始行情'!E37-1 -> -0.0090678273 | M4: =('原始行情'!E50+'原始行情'!F50)/'原始行情'!E38-1 -> 0.021423635 | N4: ='原始行情'!G39/'原始行情'!G27-1 -> 0.01272698 | O4: =SUMPRODUCT(B4:M4,'参数设置'!$E$4:$E$15) -> 0.014934171 | P4: =P3*(1+O4) -> 1.0856929 | Q4: =Q3*(1+N4) -> 1.07026 | R4: =P4/MAX($P$2:P4)-1 -> 0
A5: 45443 | B5: =('原始行情'!E51+'原始行情'!F51)/'原始行情'!E39-1 -> -0.023171988 | C5: =('原始行情'!E52+'原始行情'!F52)/'原始行情'!E40-1 -> -0.021178637 | D5: =('原始行情'!E53+'原始行情'!F53)/'原始行情'!E41-1 -> 0.025301205 | E5: =('原始行情'!E54+'原始行情'!F54)/'原始行情'!E42-1 -> 0.013936098 | F5: =('原始行情'!E55+'原始行情'!F55)/'原始行情'!E43-1 -> -0.015260323 | G5: =('原始行情'!E56+'原始行情'!F56)/'原始行情'!E44-1 -> 0.020917136 | H5: =('原始行情'!E57+'原始行情'!F57)/'原始行情'!E45-1 -> 0.032282282 | I5: =('原始行情'!E58+'原始行情'!F58)/'原始行情'!E46-1 -> -0.011527378 | J5: =('原始行情'!E59+'原始行情'!F59)/'原始行情'!E47-1 -> -0.010113519 | K5: =('原始行情'!E60+'原始行情'!F60)/'原始行情'!E48-1 -> 0.01838451 | L5: =('原始行情'!E61+'原始行情'!F61)/'原始行情'!E49-1 -> -0.014824305 | M5: =('原始行情'!E62+'原始行情'!F62)/'原始行情'!E50-1 -> -0.031968877 | N5: ='原始行情'!G51/'原始行情'!G39-1 -> -0.0030179583 | O5: =SUMPRODUCT(B5:M5,'参数设置'!$E$4:$E$15) -> -0.0014502137 | P5: =P4*(1+O5) -> 1.0841184 | Q5: =Q4*(1+N5) -> 1.06703 | R5: =P5/MAX($P$2:P5)-1 -> -0.0014502137
A6: 45473 | B6: =('原始行情'!E63+'原始行情'!F63)/'原始行情'!E51-1 -> -0.030047443 | C6: =('原始行情'!E64+'原始行情'!F64)/'原始行情'!E52-1 -> 0.0095014111 | D6: =('原始行情'!E65+'原始行情'!F65)/'原始行情'!E53-1 -> 0.018566392 | E6: =('原始行情'!E66+'原始行情'!F66)/'原始行情'!E54-1 -> -0.015219578 | F6: =('原始行情'!E67+'原始行情'!F67)/'原始行情'!E55-1 -> 0.023032513 | G6: =('原始行情'!E68+'原始行情'!F68)/'原始行情'!E56-1 -> 0.0078802206 | H6: =('原始行情'!E69+'原始行情'!F69)/'原始行情'!E57-1 -> -0.015951515 | I6: =('原始行情'!E70+'原始行情'!F70)/'原始行情'!E58-1 -> 0.022516259 | J6: =('原始行情'!E71+'原始行情'!F71)/'原始行情'!E59-1 -> -0.015929942 | K6: =('原始行情'!E72+'原始行情'!F72)/'原始行情'!E60-1 -> -0.031150374 | L6: =('原始行情'!E73+'原始行情'!F73)/'原始行情'!E61-1 -> 0.0092885008 | M6: =('原始行情'!E74+'原始行情'!F74)/'原始行情'!E62-1 -> -0.027223484 | N6: ='原始行情'!G63/'原始行情'!G51-1 -> -0.010290245 | O6: =SUMPRODUCT(B6:M6,'参数设置'!$E$4:$E$15) -> -0.0031378237 | P6: =P5*(1+O6) -> 1.0807167 | Q6: =Q5*(1+N6) -> 1.05605 | R6: =P6/MAX($P$2:P6)-1 -> -0.0045834869
A7: 45504 | B7: =('原始行情'!E75+'原始行情'!F75)/'原始行情'!E63-1 -> -0.021834061 | C7: =('原始行情'!E76+'原始行情'!F76)/'原始行情'!E64-1 -> 0.031820309 | D7: =('原始行情'!E77+'原始行情'!F77)/'原始行情'!E65-1 -> -0.0084942085 | E7: =('原始行情'!E78+'原始行情'!F78)/'原始行情'!E66-1 -> 0.022898154 | F7: =('原始行情'!E79+'原始行情'!F79)/'原始行情'!E67-1 -> 0.011627907 | G7: =('原始行情'!E80+'原始行情'!F80)/'原始行情'!E68-1 -> -0.013078734 | H7: =('原始行情'!E81+'原始行情'!F81)/'原始行情'!E69-1 -> 0.024727992 | I7: =('原始行情'!E82+'原始行情'!F82)/'原始行情'!E70-1 -> -0.028615452 | J7: =('原始行情'!E83+'原始行情'!F83)/'原始行情'!E71-1 -> 0.0048915355 | K7: =('原始行情'!E84+'原始行情'!F84)/'原始行情'!E72-1 -> -0.01810585 | L7: =('原始行情'!E85+'原始行情'!F85)/'原始行情'!E73-1 -> -0.017919823 | M7: =('原始行情'!E86+'原始行情'!F86)/'原始行情'!E74-1 -> 0.015326361 | N7: ='原始行情'!G75/'原始行情'!G63-1 -> -0.0041380616 | O7: =SUMPRODUCT(B7:M7,'参数设置'!$E$4:$E$15) -> 0.00049330939 | P7: =P6*(1+O7) -> 1.0812498 | Q7: =Q6*(1+N7) -> 1.05168 | R7: =P7/MAX($P$2:P7)-1 -> -0.0040924386
A8: 45535 | B8: =('原始行情'!E87+'原始行情'!F87)/'原始行情'!E75-1 -> -0.030691964 | C8: =('原始行情'!E88+'原始行情'!F88)/'原始行情'!E76-1 -> -0.00861678 | D8: =('原始行情'!E89+'原始行情'!F89)/'原始行情'!E77-1 -> -0.04088785 | E8: =('原始行情'!E90+'原始行情'!F90)/'原始行情'!E78-1 -> -0.010691614 | F8: =('原始行情'!E91+'原始行情'!F91)/'原始行情'!E79-1 -> -0.066018273 | G8: =('原始行情'!E92+'原始行情'!F92)/'原始行情'!E80-1 -> -0.030214683 | H8: =('原始行情'!E93+'原始行情'!F93)/'原始行情'!E81-1 -> -0.057915058 | I8: =('原始行情'!E94+'原始行情'!F94)/'原始行情'!E82-1 -> -0.016088828 | J8: =('原始行情'!E95+'原始行情'!F95)/'原始行情'!E83-1 -> -0.074920635 | K8: =('原始行情'!E96+'原始行情'!F96)/'原始行情'!E84-1 -> -0.0295846 | L8: =('原始行情'!E97+'原始行情'!F97)/'原始行情'!E85-1 -> -0.071670429 | M8: =('原始行情'!E98+'原始行情'!F98)/'原始行情'!E86-1 -> -0.031433138 | N8: ='原始行情'!G87/'原始行情'!G75-1 -> -0.04293131 | O8: =SUMPRODUCT(B8:M8,'参数设置'!$E$4:$E$15) -> -0.039343481 | P8: =P7*(1+O8) -> 1.0387097 | Q8: =Q7*(1+N8) -> 1.00653 | R8: =P8/MAX($P$2:P8)-1 -> -0.043274909
A9: 45565 | B9: =('原始行情'!E99+'原始行情'!F99)/'原始行情'!E87-1 -> 0.043177893 | C9: =('原始行情'!E100+'原始行情'!F100)/'原始行情'!E88-1 -> 0.026075023 | D9: =('原始行情'!E101+'原始行情'!F101)/'原始行情'!E89-1 -> 0.059277304 | E9: =('原始行情'!E102+'原始行情'!F102)/'原始行情'!E90-1 -> 0.021952043 | F9: =('原始行情'!E103+'原始行情'!F103)/'原始行情'!E91-1 -> 0.058378037 | G9: =('原始行情'!E104+'原始行情'!F104)/'原始行情'!E92-1 -> 0.010112052 | H9: =('原始行情'!E105+'原始行情'!F105)/'原始行情'!E93-1 -> 0.039446721 | I9: =('原始行情'!E106+'原始行情'!F106)/'原始行情'!E94-1 -> -0.0066789498 | J9: =('原始行情'!E107+'原始行情'!F107)/'原始行情'!E95-1 -> 0.044154656 | K9: =('原始行情'!E108+'原始行情'!F108)/'原始行情'!E96-1 -> 0.0079348507 | L9: =('原始行情'!E109+'原始行情'!F109)/'原始行情'!E97-1 -> 0.060182371 | M9: =('原始行情'!E110+'原始行情'!F110)/'原始行情'!E98-1 -> 0.03520352 | N9: ='原始行情'!G99/'原始行情'!G87-1 -> 0.028593286 | O9: =SUMPRODUCT(B9:M9,'参数设置'!$E$4:$E$15) -> 0.034692839 | P9: =P8*(1+O9) -> 1.0747454 | Q9: =Q8*(1+N9) -> 1.03531 | R9: =P9/MAX($P$2:P9)-1 -> -0.010083399
A10: 45596 | B10: =('原始行情'!E111+'原始行情'!F111)/'原始行情'!E99-1 -> 0.061810155 | C10: =('原始行情'!E112+'原始行情'!F112)/'原始行情'!E100-1 -> 0.017833259 | D10: =('原始行情'!E113+'原始行情'!F113)/'原始行情'!E101-1 -> 0.063242622 | E10: =('原始行情'!E114+'原始行情'!F114)/'原始行情'!E102-1 -> 0.034038334 | F10: =('原始行情'!E115+'原始行情'!F115)/'原始行情'!E103-1 -> 0.032200358 | G10: =('原始行情'!E116+'原始行情'!F116)/'原始行情'!E104-1 -> 0.056006494 | H10: =('原始行情'!E117+'原始行情'!F117)/'原始行情'!E105-1 -> -0.0061606703 | I10: =('原始行情'!E118+'原始行情'!F118)/'原始行情'!E106-1 -> 0.049617436 | J10: =('原始行情'!E119+'原始行情'!F119)/'原始行情'!E107-1 -> 0.015337423 | K10: =('原始行情'!E120+'原始行情'!F120)/'原始行情'!E108-1 -> 0.046405635 | L10: =('原始行情'!E121+'原始行情'!F121)/'原始行情'!E109-1 -> 0.064220183 | M10: =('原始行情'!E122+'原始行情'!F122)/'原始行情'!E110-1 -> 0.042685087 | N10: ='原始行情'!G111/'原始行情'!G99-1 -> 0.034888101 | O10: =SUMPRODUCT(B10:M10,'参数设置'!$E$4:$E$15) -> 0.039667718 | P10: =P9*(1+O10) -> 1.1173781 | Q10: =Q9*(1+N10) -> 1.07143 | R10: =P10/MAX($P$2:P10)-1 -> 0
A11: 45626 | B11: =('原始行情'!E123+'原始行情'!F123)/'原始行情'!E111-1 -> 0.087318087 | C11: =('原始行情'!E124+'原始行情'!F124)/'原始行情'!E112-1 -> 0.05957074 | D11: =('原始行情'!E125+'原始行情'!F125)/'原始行情'!E113-1 -> 0.058038933 | E11: =('原始行情'!E126+'原始行情'!F126)/'原始行情'!E114-1 -> 0.10035155 | F11: =('原始行情'!E127+'原始行情'!F127)/'原始行情'!E115-1 -> 0.060080878 | G11: =('原始行情'!E128+'原始行情'!F128)/'原始行情'!E116-1 -> 0.079938509 | H11: =('原始行情'!E129+'原始行情'!F129)/'原始行情'!E117-1 -> 0.068931317 | I11: =('原始行情'!E130+'原始行情'!F130)/'原始行情'!E118-1 -> 0.039098741 | J11: =('原始行情'!E131+'原始行情'!F131)/'原始行情'!E119-1 -> 0.075528701 | K11: =('原始行情'!E132+'原始行情'!F132)/'原始行情'!E120-1 -> 0.10532568 | L11: =('原始行情'!E133+'原始行情'!F133)/'原始行情'!E121-1 -> 0.076329023 | M11: =('原始行情'!E134+'原始行情'!F134)/'原始行情'!E122-1 -> 0.12332258 | N11: ='原始行情'!G123/'原始行情'!G111-1 -> 0.070774572 | O11: =SUMPRODUCT(B11:M11,'参数设置'!$E$4:$E$15) -> 0.076413881 | P11: =P10*(1+O11) -> 1.2027613 | Q11: =Q10*(1+N11) -> 1.14726 | R11: =P11/MAX($P$2:P11)-1 -> 0
A12: 45657 | B12: =('原始行情'!E135+'原始行情'!F135)/'原始行情'!E123-1 -> 0.023900574 | C12: =('原始行情'!E136+'原始行情'!F136)/'原始行情'!E124-1 -> 0.023563456 | D12: =('原始行情'!E137+'原始行情'!F137)/'原始行情'!E125-1 -> -0.019761499 | E12: =('原始行情'!E138+'原始行情'!F138)/'原始行情'!E126-1 -> -0.0052279988 | F12: =('原始行情'!E139+'原始行情'!F139)/'原始行情'!E127-1 -> 0.020980926 | G12: =('原始行情'!E140+'原始行情'!F140)/'原始行情'!E128-1 -> -0.0080664294 | H12: =('原始行情'!E141+'原始行情'!F141)/'原始行情'!E129-1 -> -0.016933426 | I12: =('原始行情'!E142+'原始行情'!F142)/'原始行情'!E130-1 -> 0.03082483 | J12: =('原始行情'!E143+'原始行情'!F143)/'原始行情'!E131-1 -> 0.024478331 | K12: =('原始行情'!E144+'原始行情'!F144)/'原始行情'!E132-1 -> -0.0048361096 | L12: =('原始行情'!E145+'原始行情'!F145)/'原始行情'!E133-1 -> 0.025362923 | M12: =('原始行情'!E146+'原始行情'!F146)/'原始行情'!E134-1 -> 0.044457886 | N12: ='原始行情'!G135/'原始行情'!G123-1 -> 0.0045848369 | O12: =SUMPRODUCT(B12:M12,'参数设置'!$E$4:$E$15) -> 0.011142815 | P12: =P11*(1+O12) -> 1.2161635 | Q12: =Q11*(1+N12) -> 1.15252 | R12: =P12/MAX($P$2:P12)-1 -> 0
A13: 45688 | B13: =('原始行情'!E147+'原始行情'!F147)/'原始行情'!E135-1 -> -0.016806723 | C13: =('原始行情'!E148+'原始行情'!F148)/'原始行情'!E136-1 -> 0.0052504039 | D13: =('原始行情'!E149+'原始行情'!F149)/'原始行情'!E137-1 -> -0.014250956 | E13: =('原始行情'!E150+'原始行情'!F150)/'原始行情'!E138-1 -> -0.047591241 | F13: =('原始行情'!E151+'原始行情'!F151)/'原始行情'!E139-1 -> -0.042967707 | G13: =('原始行情'!E152+'原始行情'!F152)/'原始行情'!E140-1 -> -0.0057402535 | H13: =('原始行情'!E153+'原始行情'!F153)/'原始行情'!E141-1 -> 0.010854176 | I13: =('原始行情'!E154+'原始行情'!F154)/'原始行情'!E142-1 -> -0.017941844 | J13: =('原始行情'!E155+'原始行情'!F155)/'原始行情'!E143-1 -> -0.024676851 | K13: =('原始行情'!E156+'原始行情'!F156)/'原始行情'!E144-1 -> 0.0077393808 | L13: =('原始行情'!E157+'原始行情'!F157)/'原始行情'!E145-1 -> 0.015296989 | M13: =('原始行情'!E158+'原始行情'!F158)/'原始行情'!E146-1 -> -0.021282757 | N13: ='原始行情'!G147/'原始行情'!G135-1 -> -0.018325062 | O13: =SUMPRODUCT(B13:M13,'参数设置'!$E$4:$E$15) -> -0.012866339 | P13: =P12*(1+O13) -> 1.2005159 | Q13: =Q12*(1+N13) -> 1.1314 | R13: =P13/MAX($P$2:P13)-1 -> -0.012866339
A14: 45716 | B14: =('原始行情'!E159+'原始行情'!F159)/'原始行情'!E147-1 -> -0.047008547 | C14: =('原始行情'!E160+'原始行情'!F160)/'原始行情'!E148-1 -> -0.029329048 | D14: =('原始行情'!E161+'原始行情'!F161)/'原始行情'!E149-1 -> -0.013046544 | E14: =('原始行情'!E162+'原始行情'!F162)/'原始行情'!E150-1 -> -0.019926426 | F14: =('原始行情'!E163+'原始行情'!F163)/'原始行情'!E151-1 -> -0.047964306 | G14: =('原始行情'!E164+'原始行情'!F164)/'原始行情'!E152-1 -> -0.060861198 | H14: =('原始行情'!E165+'原始行情'!F165)/'原始行情'!E153-1 -> -0.024276377 | I14: =('原始行情'!E166+'原始行情'!F166)/'原始行情'!E154-1 -> 0.003149937 | J14: =('原始行情'!E167+'原始行情'!F167)/'原始行情'!E155-1 -> 0.0092369478 | K14: =('原始行情'!E168+'原始行情'!F168)/'原始行情'!E156-1 -> -0.010358993 | L14: =('原始行情'!E169+'原始行情'!F169)/'原始行情'!E157-1 -> -0.044077577 | M14: =('原始行情'!E170+'原始行情'!F170)/'原始行情'!E158-1 -> -0.061686391 | N14: ='原始行情'!G159/'原始行情'!G147-1 -> -0.03127983 | O14: =SUMPRODUCT(B14:M14,'参数设置'!$E$4:$E$15) -> -0.028579615 | P14: =P13*(1+O14) -> 1.1662056 | Q14: =Q13*(1+N14) -> 1.09601 | R14: =P14/MAX($P$2:P14)-1 -> -0.041078239
A15: 45747 | B15: =('原始行情'!E171+'原始行情'!F171)/'原始行情'!E159-1 -> -0.053313403 | C15: =('原始行情'!E172+'原始行情'!F172)/'原始行情'!E160-1 -> -0.051738411 | D15: =('原始行情'!E173+'原始行情'!F173)/'原始行情'!E161-1 -> -0.036441586 | E15: =('原始行情'!E174+'原始行情'!F174)/'原始行情'!E162-1 -> -0.015639662 | F15: =('原始行情'!E175+'原始行情'!F175)/'原始行情'!E163-1 -> -0.0052724077 | G15: =('原始行情'!E176+'原始行情'!F176)/'原始行情'!E164-1 -> -0.0023053279 | H15: =('原始行情'!E177+'原始行情'!F177)/'原始行情'!E165-1 -> 0.0064593301 | I15: =('原始行情'!E178+'原始行情'!F178)/'原始行情'!E166-1 -> -0.012978857 | J15: =('原始行情'!E179+'原始行情'!F179)/'原始行情'!E167-1 -> -0.036211699 | K15: =('原始行情'!E180+'原始行情'!F180)/'原始行情'!E168-1 -> -0.046201047 | L15: =('原始行情'!E181+'原始行情'!F181)/'原始行情'!E169-1 -> -0.044936284 | M15: =('原始行情'!E182+'原始行情'!F182)/'原始行情'!E170-1 -> -0.03531452 | N15: ='原始行情'!G171/'原始行情'!G159-1 -> -0.027536245 | O15: =SUMPRODUCT(B15:M15,'参数设置'!$E$4:$E$15) -> -0.028173916 | P15: =P14*(1+O15) -> 1.1333491 | Q15: =Q14*(1+N15) -> 1.06583 | R15: =P15/MAX($P$2:P15)-1 -> -0.06809482
A16: 45777 | B16: =('原始行情'!E183+'原始行情'!F183)/'原始行情'!E171-1 -> -0.072105263 | C16: =('原始行情'!E184+'原始行情'!F184)/'原始行情'!E172-1 -> -0.082060236 | D16: =('原始行情'!E185+'原始行情'!F185)/'原始行情'!E173-1 -> -0.086021505 | E16: =('原始行情'!E186+'原始行情'!F186)/'原始行情'!E174-1 -> -0.085795996 | F16: =('原始行情'!E187+'原始行情'!F187)/'原始行情'!E175-1 -> -0.08745583 | G16: =('原始行情'!E188+'原始行情'!F188)/'原始行情'!E176-1 -> -0.083953787 | H16: =('原始行情'!E189+'原始行情'!F189)/'原始行情'!E177-1 -> -0.035179463 | I16: =('原始行情'!E190+'原始行情'!F190)/'原始行情'!E178-1 -> -0.035206787 | J16: =('原始行情'!E191+'原始行情'!F191)/'原始行情'!E179-1 -> -0.04314616 | K16: =('原始行情'!E192+'原始行情'!F192)/'原始行情'!E180-1 -> -0.048817408 | L16: =('原始行情'!E193+'原始行情'!F193)/'原始行情'!E181-1 -> -0.056355337 | M16: =('原始行情'!E194+'原始行情'!F194)/'原始行情'!E182-1 -> -0.064879882 | N16: ='原始行情'!G183/'原始行情'!G171-1 -> -0.064090896 | O16: =SUMPRODUCT(B16:M16,'参数设置'!$E$4:$E$15) -> -0.065711192 | P16: =P15*(1+O16) -> 1.0588753 | Q16: =Q15*(1+N16) -> 0.99752 | R16: =P16/MAX($P$2:P16)-1 -> -0.12933142
A17: 45808 | B17: =('原始行情'!E195+'原始行情'!F195)/'原始行情'!E183-1 -> 0.0034032898 | C17: =('原始行情'!E196+'原始行情'!F196)/'原始行情'!E184-1 -> 0.011887779 | D17: =('原始行情'!E197+'原始行情'!F197)/'原始行情'!E185-1 -> 0.021095335 | E17: =('原始行情'!E198+'原始行情'!F198)/'原始行情'!E186-1 -> 0.029892249 | F17: =('原始行情'!E199+'原始行情'!F199)/'原始行情'!E187-1 -> 0.031945789 | G17: =('原始行情'!E200+'原始行情'!F200)/'原始行情'!E188-1 -> 0.035874439 | H17: =('原始行情'!E201+'原始行情'!F201)/'原始行情'!E189-1 -> 0.025868441 | I17: =('原始行情'!E202+'原始行情'!F202)/'原始行情'!E190-1 -> 0.02396131 | J17: =('原始行情'!E203+'原始行情'!F203)/'原始行情'!E191-1 -> 0.01596548 | K17: =('原始行情'!E204+'原始行情'!F204)/'原始行情'!E192-1 -> 0.013526954 | L17: =('原始行情'!E205+'原始行情'!F205)/'原始行情'!E193-1 -> 0.013023256 | M17: =('原始行情'!E206+'原始行情'!F206)/'原始行情'!E194-1 -> 0.015728766 | N17: ='原始行情'!G195/'原始行情'!G183-1 -> 0.0144759 | O17: =SUMPRODUCT(B17:M17,'参数设置'!$E$4:$E$15) -> 0.019909538 | P17: =P16*(1+O17) -> 1.0799571 | Q17: =Q16*(1+N17) -> 1.01196 | R17: =P17/MAX($P$2:P17)-1 -> -0.11199681
A18: 45838 | B18: =('原始行情'!E207+'原始行情'!F207)/'原始行情'!E195-1 -> 0.041831543 | C18: =('原始行情'!E208+'原始行情'!F208)/'原始行情'!E196-1 -> 0.058364662 | D18: =('原始行情'!E209+'原始行情'!F209)/'原始行情'!E197-1 -> 0.071275328 | E18: =('原始行情'!E210+'原始行情'!F210)/'原始行情'!E198-1 -> 0.078839015 | F18: =('原始行情'!E211+'原始行情'!F211)/'原始行情'!E199-1 -> 0.075297061 | G18: =('原始行情'!E212+'原始行情'!F212)/'原始行情'!E200-1 -> 0.070075758 | H18: =('原始行情'!E213+'原始行情'!F213)/'原始行情'!E201-1 -> 0.038472622 | I18: =('原始行情'!E214+'原始行情'!F214)/'原始行情'!E202-1 -> 0.027565479 | J18: =('原始行情'!E215+'原始行情'!F215)/'原始行情'!E203-1 -> 0.013930771 | K18: =('原始行情'!E216+'原始行情'!F216)/'原始行情'!E204-1 -> 0.0087929342 | L18: =('原始行情'!E217+'原始行情'!F217)/'原始行情'!E205-1 -> 0.0097337006 | M18: =('原始行情'!E218+'原始行情'!F218)/'原始行情'!E206-1 -> 0.017412251 | N18: ='原始行情'!G207/'原始行情'!G195-1 -> 0.031266058 | O18: =SUMPRODUCT(B18:M18,'参数设置'!$E$4:$E$15) -> 0.043947961 | P18: =P17*(1+O18) -> 1.127419 | Q18: =Q17*(1+N18) -> 1.0436 | R18: =P18/MAX($P$2:P18)-1 -> -0.072970881
A19: 45869 | B19: =('原始行情'!E219+'原始行情'!F219)/'原始行情'!E207-1 -> 0.053405995 | C19: =('原始行情'!E220+'原始行情'!F220)/'原始行情'!E208-1 -> 0.058849755 | D19: =('原始行情'!E221+'原始行情'!F221)/'原始行情'!E209-1 -> 0.052122115 | E19: =('原始行情'!E222+'原始行情'!F222)/'原始行情'!E210-1 -> 0.040188383 | F19: =('原始行情'!E223+'原始行情'!F223)/'原始行情'!E211-1 -> 0.02772913 | G19: =('原始行情'!E224+'原始行情'!F224)/'原始行情'!E212-1 -> 0.030449125 | H19: =('原始行情'!E225+'原始行情'!F225)/'原始行情'!E213-1 -> 0.01926201 | I19: =('原始行情'!E226+'原始行情'!F226)/'原始行情'!E214-1 -> 0.037106918 | J19: =('原始行情'!E227+'原始行情'!F227)/'原始行情'!E215-1 -> 0.046457852 | K19: =('原始行情'!E228+'原始行情'!F228)/'原始行情'!E216-1 -> 0.051552431 | L19: =('原始行情'!E229+'原始行情'!F229)/'原始行情'!E217-1 -> 0.047280029 | M19: =('原始行情'!E230+'原始行情'!F230)/'原始行情'!E218-1 -> 0.039545146 | N19: ='原始行情'!G219/'原始行情'!G207-1 -> 0.033518589 | O19: =SUMPRODUCT(B19:M19,'参数设置'!$E$4:$E$15) -> 0.042269415 | P19: =P18*(1+O19) -> 1.1750743 | Q19: =Q18*(1+N19) -> 1.07858 | R19: =P19/MAX($P$2:P19)-1 -> -0.033785903
A20: 45900 | B20: =('原始行情'!E231+'原始行情'!F231)/'原始行情'!E219-1 -> 0.04500776 | C20: =('原始行情'!E232+'原始行情'!F232)/'原始行情'!E220-1 -> 0.027789474 | D20: =('原始行情'!E233+'原始行情'!F233)/'原始行情'!E221-1 -> 0.013446568 | E20: =('原始行情'!E234+'原始行情'!F234)/'原始行情'!E222-1 -> 0.022638092 | F20: =('原始行情'!E235+'原始行情'!F235)/'原始行情'!E223-1 -> 0.042885544 | G20: =('原始行情'!E236+'原始行情'!F236)/'原始行情'!E224-1 -> 0.055405073 | H20: =('原始行情'!E237+'原始行情'!F237)/'原始行情'!E225-1 -> 0.024590164 | I20: =('原始行情'!E238+'原始行情'!F238)/'原始行情'!E226-1 -> -0.0016171417 | J20: =('原始行情'!E239+'原始行情'!F239)/'原始行情'!E227-1 -> -0.013057453 | K20: =('原始行情'!E240+'原始行情'!F240)/'原始行情'!E228-1 -> 0.011142061 | L20: =('原始行情'!E241+'原始行情'!F241)/'原始行情'!E229-1 -> 0.045668468 | M20: =('原始行情'!E242+'原始行情'!F242)/'原始行情'!E230-1 -> 0.060571429 | N20: ='原始行情'!G231/'原始行情'!G219-1 -> 0.021732278 | O20: =SUMPRODUCT(B20:M20,'参数设置'!$E$4:$E$15) -> 0.027608156 | P20: =P19*(1+O20) -> 1.2075159 | Q20: =Q19*(1+N20) -> 1.10202 | R20: =P20/MAX($P$2:P20)-1 -> -0.0071105134
A21: 45930 | B21: =('原始行情'!E243+'原始行情'!F243)/'原始行情'!E231-1 -> 0.052970297 | C21: =('原始行情'!E244+'原始行情'!F244)/'原始行情'!E232-1 -> 0.032773454 | D21: =('原始行情'!E245+'原始行情'!F245)/'原始行情'!E233-1 -> 0.053072626 | E21: =('原始行情'!E246+'原始行情'!F246)/'原始行情'!E234-1 -> 0.086186541 | F21: =('原始行情'!E247+'原始行情'!F247)/'原始行情'!E235-1 -> 0.071350763 | G21: =('原始行情'!E248+'原始行情'!F248)/'原始行情'!E236-1 -> 0.03989734 | H21: =('原始行情'!E249+'原始行情'!F249)/'原始行情'!E237-1 -> 0.013333333 | I21: =('原始行情'!E250+'原始行情'!F250)/'原始行情'!E238-1 -> 0.053654586 | J21: =('原始行情'!E251+'原始行情'!F251)/'原始行情'!E239-1 -> 0.059230613 | K21: =('原始行情'!E252+'原始行情'!F252)/'原始行情'!E240-1 -> 0.037832874 | L21: =('原始行情'!E253+'原始行情'!F253)/'原始行情'!E241-1 -> 0.045174196 | M21: =('原始行情'!E254+'原始行情'!F254)/'原始行情'!E242-1 -> 0.090517241 | N21: ='原始行情'!G243/'原始行情'!G231-1 -> 0.04907352 | O21: =SUMPRODUCT(B21:M21,'参数设置'!$E$4:$E$15) -> 0.052492468 | P21: =P20*(1+O21) -> 1.2709014 | Q21: =Q20*(1+N21) -> 1.1561 | R21: =P21/MAX($P$2:P21)-1 -> 0
A22: 45961 | B22: =('原始行情'!E255+'原始行情'!F255)/'原始行情'!E243-1 -> -0.0051716032 | C22: =('原始行情'!E256+'原始行情'!F256)/'原始行情'!E244-1 -> -0.010313368 | D22: =('原始行情'!E257+'原始行情'!F257)/'原始行情'!E245-1 -> 0.023872679 | E22: =('原始行情'!E258+'原始行情'!F258)/'原始行情'!E246-1 -> -0.0016304348 | F22: =('原始行情'!E259+'原始行情'!F259)/'原始行情'!E247-1 -> -0.040162684 | G22: =('原始行情'!E260+'原始行情'!F260)/'原始行情'!E248-1 -> -0.0083015481 | H22: =('原始行情'!E261+'原始行情'!F261)/'原始行情'!E249-1 -> 0.0059210526 | I22: =('原始行情'!E262+'原始行情'!F262)/'原始行情'!E250-1 -> -0.0311299 | J22: =('原始行情'!E263+'原始行情'!F263)/'原始行情'!E251-1 -> -0.01633359 | K22: =('原始行情'!E264+'原始行情'!F264)/'原始行情'!E252-1 -> 0.022119979 | L22: =('原始行情'!E265+'原始行情'!F265)/'原始行情'!E253-1 -> -0.0043062201 | M22: =('原始行情'!E266+'原始行情'!F266)/'原始行情'!E254-1 -> -0.014539808 | N22: ='原始行情'!G255/'原始行情'!G243-1 -> -0.0084594758 | O22: =SUMPRODUCT(B22:M22,'参数设置'!$E$4:$E$15) -> -0.0064623503 | P22: =P21*(1+O22) -> 1.2626884 | Q22: =Q21*(1+N22) -> 1.14632 | R22: =P22/MAX($P$2:P22)-1 -> -0.0064623503
A23: 45991 | B23: =('原始行情'!E267+'原始行情'!F267)/'原始行情'!E255-1 -> -0.018431002 | C23: =('原始行情'!E268+'原始行情'!F268)/'原始行情'!E256-1 -> 0.010420842 | D23: =('原始行情'!E269+'原始行情'!F269)/'原始行情'!E257-1 -> 0.0071243523 | E23: =('原始行情'!E270+'原始行情'!F270)/'原始行情'!E258-1 -> -0.035655961 | F23: =('原始行情'!E271+'原始行情'!F271)/'原始行情'!E259-1 -> -0.001059322 | G23: =('原始行情'!E272+'原始行情'!F272)/'原始行情'!E260-1 -> -0.016289593 | H23: =('原始行情'!E273+'原始行情'!F273)/'原始行情'!E261-1 -> -0.031611075 | I23: =('原始行情'!E274+'原始行情'!F274)/'原始行情'!E262-1 -> 0.018445061 | J23: =('原始行情'!E275+'原始行情'!F275)/'原始行情'!E263-1 -> -0.0099628834 | K23: =('原始行情'!E276+'原始行情'!F276)/'原始行情'!E264-1 -> -0.012292244 | L23: =('原始行情'!E277+'原始行情'!F277)/'原始行情'!E265-1 -> 0.031234983 | M23: =('原始行情'!E278+'原始行情'!F278)/'原始行情'!E266-1 -> -0.0090244951 | N23: ='原始行情'!G267/'原始行情'!G255-1 -> -0.0084618606 | O23: =SUMPRODUCT(B23:M23,'参数设置'!$E$4:$E$15) -> -0.0054406721 | P23: =P22*(1+O23) -> 1.2558186 | Q23: =Q22*(1+N23) -> 1.13662 | R23: =P23/MAX($P$2:P23)-1 -> -0.011867863
A24: 46022 | B24: =('原始行情'!E279+'原始行情'!F279)/'原始行情'!E267-1 -> -0.012999519 | C24: =('原始行情'!E280+'原始行情'!F280)/'原始行情'!E268-1 -> 0.029750099 | D24: =('原始行情'!E281+'原始行情'!F281)/'原始行情'!E269-1 -> -0.019935691 | E24: =('原始行情'!E282+'原始行情'!F282)/'原始行情'!E270-1 -> 0.0090318939 | F24: =('原始行情'!E283+'原始行情'!F283)/'原始行情'!E271-1 -> -0.0015906681 | G24: =('原始行情'!E284+'原始行情'!F284)/'原始行情'!E272-1 -> -0.015869365 | H24: =('原始行情'!E285+'原始行情'!F285)/'原始行情'!E273-1 -> 0.027239982 | I24: =('原始行情'!E286+'原始行情'!F286)/'原始行情'!E274-1 -> -0.01285297 | J24: =('原始行情'!E287+'原始行情'!F287)/'原始行情'!E275-1 -> 0.032754538 | K24: =('原始行情'!E288+'原始行情'!F288)/'原始行情'!E276-1 -> 0.012094654 | L24: =('原始行情'!E289+'原始行情'!F289)/'原始行情'!E277-1 -> 0.014756135 | M24: =('原始行情'!E290+'原始行情'!F290)/'原始行情'!E278-1 -> 0.037583117 | N24: ='原始行情'!G279/'原始行情'!G267-1 -> 0.0037039644 | O24: =SUMPRODUCT(B24:M24,'参数设置'!$E$4:$E$15) -> 0.0075541824 | P24: =P23*(1+O24) -> 1.2653052 | Q24: =Q23*(1+N24) -> 1.14083 | R24: =P24/MAX($P$2:P24)-1 -> -0.0044033325

Sheet 压力测试
A1: 股票组合情景压力测试
A2: 按行业冲击映射至每只股票，计算持仓市值和情景损益；负值代表亏损。
J3: 情景 | K3: 组合损益 | L3: 损益率 | M3: 风险判断
A4: 情景 | B4: 股票代码 | C4: 行业 | D4: 目标权重 | E4: 行业冲击 | F4: 持仓市值 | G4: 情景损益 | J4: 温和回撤 | K4: =SUM(G5:G16) -> -523000 | L4: =K4/'参数设置'!$B$3 -> -0.0523 | M4: =IF(L4<=-15%,"高风险",IF(L4<0,"中风险","正向情景")) -> 中风险
A5: 温和回撤 | B5: S001 | C5: 科技 | D5: ='参数设置'!E4 -> 0.1 | E5: ='参数设置'!B22 -> -0.08 | F5: =D5*'参数设置'!$B$3 -> 1000000 | G5: =E5*F5 -> -80000 | J5: 流动性冲击 | K5: =SUM(G17:G28) -> -1676000 | L5: =K5/'参数设置'!$B$3 -> -0.1676 | M5: =IF(L5<=-15%,"高风险",IF(L5<0,"中风险","正向情景")) -> 高风险
A6: 温和回撤 | B6: S002 | C6: 科技 | D6: ='参数设置'!E5 -> 0.09 | E6: ='参数设置'!B22 -> -0.08 | F6: =D6*'参数设置'!$B$3 -> 900000 | G6: =E6*F6 -> -72000 | J6: 增长反弹 | K6: =SUM(G29:G40) -> 986000 | L6: =K6/'参数设置'!$B$3 -> 0.0986 | M6: =IF(L6<=-15%,"高风险",IF(L6<0,"中风险","正向情景")) -> 正向情景
A7: 温和回撤 | B7: S003 | C7: 金融 | D7: ='参数设置'!E6 -> 0.1 | E7: ='参数设置'!B23 -> -0.05 | F7: =D7*'参数设置'!$B$3 -> 1000000 | G7: =E7*F7 -> -50000
A8: 温和回撤 | B8: S004 | C8: 金融 | D8: ='参数设置'!E7 -> 0.08 | E8: ='参数设置'!B23 -> -0.05 | F8: =D8*'参数设置'!$B$3 -> 800000 | G8: =E8*F8 -> -40000
A9: 温和回撤 | B9: S005 | C9: 医药 | D9: ='参数设置'!E8 -> 0.09 | E9: ='参数设置'!B24 -> -0.03 | F9: =D9*'参数设置'!$B$3 -> 900000 | G9: =E9*F9 -> -27000
A10: 温和回撤 | B10: S006 | C10: 医药 | D10: ='参数设置'!E9 -> 0.07 | E10: ='参数设置'!B24 -> -0.03 | F10: =D10*'参数设置'!$B$3 -> 700000 | G10: =E10*F10 -> -21000
A11: 温和回撤 | B11: S007 | C11: 消费 | D11: ='参数设置'!E10 -> 0.09 | E11: ='参数设置'!B25 -> -0.04 | F11: =D11*'参数设置'!$B$3 -> 900000 | G11: =E11*F11 -> -36000
A12: 温和回撤 | B12: S008 | C12: 消费 | D12: ='参数设置'!E11 -> 0.08 | E12: ='参数设置'!B25 -> -0.04 | F12: =D12*'参数设置'!$B$3 -> 800000 | G12: =E12*F12 -> -32000
A13: 温和回撤 | B13: S009 | C13: 能源 | D13: ='参数设置'!E12 -> 0.08 | E13: ='参数设置'!B26 -> -0.06 | F13: =D13*'参数设置'!$B$3 -> 800000 | G13: =E13*F13 -> -48000
A14: 温和回撤 | B14: S010 | C14: 能源 | D14: ='参数设置'!E13 -> 0.07 | E14: ='参数设置'!B26 -> -0.06 | F14: =D14*'参数设置'!$B$3 -> 700000 | G14: =E14*F14 -> -42000
A15: 温和回撤 | B15: S011 | C15: 工业 | D15: ='参数设置'!E14 -> 0.08 | E15: ='参数设置'!B27 -> -0.05 | F15: =D15*'参数设置'!$B$3 -> 800000 | G15: =E15*F15 -> -40000
A16: 温和回撤 | B16: S012 | C16: 工业 | D16: ='参数设置'!E15 -> 0.07 | E16: ='参数设置'!B27 -> -0.05 | F16: =D16*'参数设置'!$B$3 -> 700000 | G16: =E16*F16 -> -35000
A17: 流动性冲击 | B17: S001 | C17: 科技 | D17: ='参数设置'!E4 -> 0.1 | E17: ='参数设置'!C22 -> -0.18 | F17: =D17*'参数设置'!$B$3 -> 1000000 | G17: =E17*F17 -> -180000
A18: 流动性冲击 | B18: S002 | C18: 科技 | D18: ='参数设置'!E5 -> 0.09 | E18: ='参数设置'!C22 -> -0.18 | F18: =D18*'参数设置'!$B$3 -> 900000 | G18: =E18*F18 -> -162000
A19: 流动性冲击 | B19: S003 | C19: 金融 | D19: ='参数设置'!E6 -> 0.1 | E19: ='参数设置'!C23 -> -0.22 | F19: =D19*'参数设置'!$B$3 -> 1000000 | G19: =E19*F19 -> -220000
A20: 流动性冲击 | B20: S004 | C20: 金融 | D20: ='参数设置'!E7 -> 0.08 | E20: ='参数设置'!C23 -> -0.22 | F20: =D20*'参数设置'!$B$3 -> 800000 | G20: =E20*F20 -> -176000
A21: 流动性冲击 | B21: S005 | C21: 医药 | D21: ='参数设置'!E8 -> 0.09 | E21: ='参数设置'!C24 -> -0.1 | F21: =D21*'参数设置'!$B$3 -> 900000 | G21: =E21*F21 -> -90000
A22: 流动性冲击 | B22: S006 | C22: 医药 | D22: ='参数设置'!E9 -> 0.07 | E22: ='参数设置'!C24 -> -0.1 | F22: =D22*'参数设置'!$B$3 -> 700000 | G22: =E22*F22 -> -70000
A23: 流动性冲击 | B23: S007 | C23: 消费 | D23: ='参数设置'!E10 -> 0.09 | E23: ='参数设置'!C25 -> -0.14 | F23: =D23*'参数设置'!$B$3 -> 900000 | G23: =E23*F23 -> -126000
A24: 流动性冲击 | B24: S008 | C24: 消费 | D24: ='参数设置'!E11 -> 0.08 | E24: ='参数设置'!C25 -> -0.14 | F24: =D24*'参数设置'!$B$3 -> 800000 | G24: =E24*F24 -> -112000
A25: 流动性冲击 | B25: S009 | C25: 能源 | D25: ='参数设置'!E12 -> 0.08 | E25: ='参数设置'!C26 -> -0.17 | F25: =D25*'参数设置'!$B$3 -> 800000 | G25: =E25*F25 -> -136000
A26: 流动性冲击 | B26: S010 | C26: 能源 | D26: ='参数设置'!E13 -> 0.07 | E26: ='参数设置'!C26 -> -0.17 | F26: =D26*'参数设置'!$B$3 -> 700000 | G26: =E26*F26 -> -119000
A27: 流动性冲击 | B27: S011 | C27: 工业 | D27: ='参数设置'!E14 -> 0.08 | E27: ='参数设置'!C27 -> -0.19 | F27: =D27*'参数设置'!$B$3 -> 800000 | G27: =E27*F27 -> -152000
A28: 流动性冲击 | B28: S012 | C28: 工业 | D28: ='参数设置'!E15 -> 0.07 | E28: ='参数设置'!C27 -> -0.19 | F28: =D28*'参数设置'!$B$3 -> 700000 | G28: =E28*F28 -> -133000
A29: 增长反弹 | B29: S001 | C29: 科技 | D29: ='参数设置'!E4 -> 0.1 | E29: ='参数设置'!D22 -> 0.16 | F29: =D29*'参数设置'!$B$3 -> 1000000 | G29: =E29*F29 -> 160000
A30: 增长反弹 | B30: S002 | C30: 科技 | D30: ='参数设置'!E5 -> 0.09 | E30: ='参数设置'!D22 -> 0.16 | F30: =D30*'参数设置'!$B$3 -> 900000 | G30: =E30*F30 -> 144000
A31: 增长反弹 | B31: S003 | C31: 金融 | D31: ='参数设置'!E6 -> 0.1 | E31: ='参数设置'!D23 -> 0.07 | F31: =D31*'参数设置'!$B$3 -> 1000000 | G31: =E31*F31 -> 70000
A32: 增长反弹 | B32: S004 | C32: 金融 | D32: ='参数设置'!E7 -> 0.08 | E32: ='参数设置'!D23 -> 0.07 | F32: =D32*'参数设置'!$B$3 -> 800000 | G32: =E32*F32 -> 56000
A33: 增长反弹 | B33: S005 | C33: 医药 | D33: ='参数设置'!E8 -> 0.09 | E33: ='参数设置'!D24 -> 0.09 | F33: =D33*'参数设置'!$B$3 -> 900000 | G33: =E33*F33 -> 81000
A34: 增长反弹 | B34: S006 | C34: 医药 | D34: ='参数设置'!E9 -> 0.07 | E34: ='参数设置'!D24 -> 0.09 | F34: =D34*'参数设置'!$B$3 -> 700000 | G34: =E34*F34 -> 63000
A35: 增长反弹 | B35: S007 | C35: 消费 | D35: ='参数设置'!E10 -> 0.09 | E35: ='参数设置'!D25 -> 0.11 | F35: =D35*'参数设置'!$B$3 -> 900000 | G35: =E35*F35 -> 99000
A36: 增长反弹 | B36: S008 | C36: 消费 | D36: ='参数设置'!E11 -> 0.08 | E36: ='参数设置'!D25 -> 0.11 | F36: =D36*'参数设置'!$B$3 -> 800000 | G36: =E36*F36 -> 88000
A37: 增长反弹 | B37: S009 | C37: 能源 | D37: ='参数设置'!E12 -> 0.08 | E37: ='参数设置'!D26 -> 0.05 | F37: =D37*'参数设置'!$B$3 -> 800000 | G37: =E37*F37 -> 40000
A38: 增长反弹 | B38: S010 | C38: 能源 | D38: ='参数设置'!E13 -> 0.07 | E38: ='参数设置'!D26 -> 0.05 | F38: =D38*'参数设置'!$B$3 -> 700000 | G38: =E38*F38 -> 35000
A39: 增长反弹 | B39: S011 | C39: 工业 | D39: ='参数设置'!E14 -> 0.08 | E39: ='参数设置'!D27 -> 0.1 | F39: =D39*'参数设置'!$B$3 -> 800000 | G39: =E39*F39 -> 80000
A40: 增长反弹 | B40: S012 | C40: 工业 | D40: ='参数设置'!E15 -> 0.07 | E40: ='参数设置'!D27 -> 0.1 | F40: =D40*'参数设置'!$B$3 -> 700000 | G40: =E40*F40 -> 70000

Sheet 投资仪表盘
A1: 股票组合投资仪表盘
A3: 组合年化收益率 | D3: 组合年化波动率 | G3: 95%单月VaR率 | J3: 最大回撤
A4: ='组合分析'!B22 -> 0.13062684 | D4: ='组合分析'!B23 -> 0.11455607 | G4: ='组合分析'!B25/'参数设置'!B3 -> 0.054399309 | J4: ='组合分析'!B27 -> -0.12933142
A7: 风险贡献最高的 5 只股票
A8: 排名 | B8: 股票代码 | C8: 股票名称 | D8: 目标权重 | E8: 月度VaR贡献
A9: 1 | B9: ='组合分析'!A6 -> S001 | C9: ='组合分析'!B6 -> 华曜科技 | D9: ='组合分析'!M6 -> 0.1 | E9: ='组合分析'!P6 -> 69186.57
A10: 2 | B10: ='组合分析'!A10 -> S005 | C10: ='组合分析'!B10 -> 远岭医药 | D10: ='组合分析'!M10 -> 0.09 | E10: ='组合分析'!P10 -> 65111.893
A11: 3 | B11: ='组合分析'!A8 -> S003 | C11: ='组合分析'!B8 -> 江海银行 | D11: ='组合分析'!M8 -> 0.1 | E11: ='组合分析'!P8 -> 63964.678
A12: 4 | B12: ='组合分析'!A9 -> S004 | C12: ='组合分析'!B9 -> 安信证券 | D12: ='组合分析'!M9 -> 0.08 | E12: ='组合分析'!P9 -> 55817.83
A13: 5 | B13: ='组合分析'!A17 -> S012 | C13: ='组合分析'!B17 -> 锐虎机械 | D13: ='组合分析'!M17 -> 0.07 | E13: ='组合分析'!P17 -> 54267

Sheet 行业风险归因
A1: 六行业协方差风险归因
A3: 月末 | B3: 科技 | C3: 金融 | D3: 医药 | E3: 消费 | F3: 能源 | G3: 工业 | H3: 加权组合收益
A4: 45351 | B4: =('月度收益'!B2*'参数设置'!E4+'月度收益'!C2*'参数设置'!E5)/B$30 -> 0.040139355 | C4: =('月度收益'!D2*'参数设置'!E6+'月度收益'!E2*'参数设置'!E7)/C$30 -> 0.02065109 | D4: =('月度收益'!F2*'参数设置'!E8+'月度收益'!G2*'参数设置'!E9)/D$30 -> 0.013669662 | E4: =('月度收益'!H2*'参数设置'!E10+'月度收益'!I2*'参数设置'!E11)/E$30 -> 0.036478075 | F4: =('月度收益'!J2*'参数设置'!E12+'月度收益'!K2*'参数设置'!E13)/F$30 -> 0.067010668 | G4: =('月度收益'!L2*'参数设置'!E14+'月度收益'!M2*'参数设置'!E15)/G$30 -> 0.04900423 | H4: =SUMPRODUCT(B4:G4,$B$30:$G$30) -> 0.037134327
A5: 45382 | B5: =('月度收益'!B3*'参数设置'!E4+'月度收益'!C3*'参数设置'!E5)/B$30 -> 0.020803854 | C5: =('月度收益'!D3*'参数设置'!E6+'月度收益'!E3*'参数设置'!E7)/C$30 -> 0.0037386423 | D5: =('月度收益'!F3*'参数设置'!E8+'月度收益'!G3*'参数设置'!E9)/D$30 -> 0.055839683 | E5: =('月度收益'!H3*'参数设置'!E10+'月度收益'!I3*'参数设置'!E11)/E$30 -> 0.038112386 | F5: =('月度收益'!J3*'参数设置'!E12+'月度收益'!K3*'参数设置'!E13)/F$30 -> 0.02042017 | G5: =('月度收益'!L3*'参数设置'!E14+'月度收益'!M3*'参数设置'!E15)/G$30 -> 0.055429624 | H5: =SUMPRODUCT(B5:G5,$B$30:$G$30) -> 0.031416612
A6: 45412 | B6: =('月度收益'!B4*'参数设置'!E4+'月度收益'!C4*'参数设置'!E5)/B$30 -> -0.0072281744 | C6: =('月度收益'!D4*'参数设置'!E6+'月度收益'!E4*'参数设置'!E7)/C$30 -> 0.02062958 | D6: =('月度收益'!F4*'参数设置'!E8+'月度收益'!G4*'参数设置'!E9)/D$30 -> 0.025813468 | E6: =('月度收益'!H4*'参数设置'!E10+'月度收益'!I4*'参数设置'!E11)/E$30 -> 0.025526482 | F6: =('月度收益'!J4*'参数设置'!E12+'月度收益'!K4*'参数设置'!E13)/F$30 -> 0.022335434 | G6: =('月度收益'!L4*'参数设置'!E14+'月度收益'!M4*'参数设置'!E15)/G$30 -> 0.0051615218 | H6: =SUMPRODUCT(B6:G6,$B$30:$G$30) -> 0.014934171
A7: 45443 | B7: =('月度收益'!B5*'参数设置'!E4+'月度收益'!C5*'参数设置'!E5)/B$30 -> -0.022227769 | C7: =('月度收益'!D5*'参数设置'!E6+'月度收益'!E5*'参数设置'!E7)/C$30 -> 0.020250046 | D7: =('月度收益'!F5*'参数设置'!E8+'月度收益'!G5*'参数设置'!E9)/D$30 -> 0.00056731521 | E7: =('月度收益'!H5*'参数设置'!E10+'月度收益'!I5*'参数设置'!E11)/E$30 -> 0.011665972 | F7: =('月度收益'!J5*'参数设置'!E12+'月度收益'!K5*'参数设置'!E13)/F$30 -> 0.0031855612 | G7: =('月度收益'!L5*'参数设置'!E14+'月度收益'!M5*'参数设置'!E15)/G$30 -> -0.022825105 | H7: =SUMPRODUCT(B7:G7,$B$30:$G$30) -> -0.0014502137
A8: 45473 | B8: =('月度收益'!B6*'参数设置'!E4+'月度收益'!C6*'参数设置'!E5)/B$30 -> -0.011313775 | C8: =('月度收益'!D6*'参数设置'!E6+'月度收益'!E6*'参数设置'!E7)/C$30 -> 0.0035504058 | D8: =('月度收益'!F6*'参数设置'!E8+'月度收益'!G6*'参数设置'!E9)/D$30 -> 0.016403385 | E8: =('月度收益'!H6*'参数设置'!E10+'月度收益'!I6*'参数设置'!E11)/E$30 -> 0.0021509669 | F8: =('月度收益'!J6*'参数设置'!E12+'月度收益'!K6*'参数设置'!E13)/F$30 -> -0.02303281 | G8: =('月度收益'!L6*'参数设置'!E14+'月度收益'!M6*'参数设置'!E15)/G$30 -> -0.0077504255 | H8: =SUMPRODUCT(B8:G8,$B$30:$G$30) -> -0.0031378237
A9: 45504 | B9: =('月度收益'!B7*'参数设置'!E4+'月度收益'!C7*'参数设置'!E5)/B$30 -> 0.0035811667 | C9: =('月度收益'!D7*'参数设置'!E6+'月度收益'!E7*'参数设置'!E7)/C$30 -> 0.0054579528 | D9: =('月度收益'!F7*'参数设置'!E8+'月度收益'!G7*'参数设置'!E9)/D$30 -> 0.00081875156 | E9: =('月度收益'!H7*'参数设置'!E10+'月度收益'!I7*'参数设置'!E11)/E$30 -> -0.00037480529 | F9: =('月度收益'!J7*'参数设置'!E12+'月度收益'!K7*'参数设置'!E13)/F$30 -> -0.0058405775 | G9: =('月度收益'!L7*'参数设置'!E14+'月度收益'!M7*'参数设置'!E15)/G$30 -> -0.0024049368 | H9: =SUMPRODUCT(B9:G9,$B$30:$G$30) -> 0.00049330939
A10: 45535 | B10: =('月度收益'!B8*'参数设置'!E4+'月度收益'!C8*'参数设置'!E5)/B$30 -> -0.020235298 | C10: =('月度收益'!D8*'参数设置'!E6+'月度收益'!E8*'参数设置'!E7)/C$30 -> -0.027467301 | D10: =('月度收益'!F8*'参数设置'!E8+'月度收益'!G8*'参数设置'!E9)/D$30 -> -0.050354202 | E10: =('月度收益'!H8*'参数设置'!E10+'月度收益'!I8*'参数设置'!E11)/E$30 -> -0.038232126 | F10: =('月度收益'!J8*'参数设置'!E12+'月度收益'!K8*'参数设置'!E13)/F$30 -> -0.053763819 | G10: =('月度收益'!L8*'参数设置'!E14+'月度收益'!M8*'参数设置'!E15)/G$30 -> -0.052893026 | H10: =SUMPRODUCT(B10:G10,$B$30:$G$30) -> -0.039343481
A11: 45565 | B11: =('月度收益'!B9*'参数设置'!E4+'月度收益'!C9*'参数设置'!E5)/B$30 -> 0.035076533 | C11: =('月度收益'!D9*'参数设置'!E6+'月度收益'!E9*'参数设置'!E7)/C$30 -> 0.042688299 | D11: =('月度收益'!F9*'参数设置'!E8+'月度收益'!G9*'参数设置'!E9)/D$30 -> 0.037261669 | E11: =('月度收益'!H9*'参数设置'!E10+'月度收益'!I9*'参数设置'!E11)/E$30 -> 0.017740523 | F11: =('月度收益'!J9*'参数设置'!E12+'月度收益'!K9*'参数设置'!E13)/F$30 -> 0.02725208 | G11: =('月度收益'!L9*'参数设置'!E14+'月度收益'!M9*'参数设置'!E15)/G$30 -> 0.048525574 | H11: =SUMPRODUCT(B11:G11,$B$30:$G$30) -> 0.034692839
A12: 45596 | B12: =('月度收益'!B10*'参数设置'!E4+'月度收益'!C10*'参数设置'!E5)/B$30 -> 0.040978994 | C12: =('月度收益'!D10*'参数设置'!E6+'月度收益'!E10*'参数设置'!E7)/C$30 -> 0.050262938 | D12: =('月度收益'!F10*'参数设置'!E8+'月度收益'!G10*'参数设置'!E9)/D$30 -> 0.042615542 | E12: =('月度收益'!H10*'参数设置'!E10+'月度收益'!I10*'参数设置'!E11)/E$30 -> 0.02008785 | F12: =('月度收益'!J10*'参数设置'!E12+'月度收益'!K10*'参数设置'!E13)/F$30 -> 0.029835922 | G12: =('月度收益'!L10*'参数设置'!E14+'月度收益'!M10*'参数设置'!E15)/G$30 -> 0.054170472 | H12: =SUMPRODUCT(B12:G12,$B$30:$G$30) -> 0.039667718
A13: 45626 | B13: =('月度收益'!B11*'参数设置'!E4+'月度收益'!C11*'参数设置'!E5)/B$30 -> 0.074174607 | C13: =('月度收益'!D11*'参数设置'!E6+'月度收益'!E11*'参数设置'!E7)/C$30 -> 0.076844541 | D13: =('月度收益'!F11*'参数设置'!E8+'月度收益'!G11*'参数设置'!E9)/D$30 -> 0.068768592 | E13: =('月度收益'!H11*'参数设置'!E10+'月度收益'!I11*'参数设置'!E11)/E$30 -> 0.054892457 | F13: =('月度收益'!J11*'参数设置'!E12+'月度收益'!K11*'参数设置'!E13)/F$30 -> 0.089433957 | G13: =('月度收益'!L11*'参数设置'!E14+'月度收益'!M11*'参数设置'!E15)/G$30 -> 0.098259347 | H13: =SUMPRODUCT(B13:G13,$B$30:$G$30) -> 0.076413881
A14: 45657 | B14: =('月度收益'!B12*'参数设置'!E4+'月度收益'!C12*'参数设置'!E5)/B$30 -> 0.023740886 | C14: =('月度收益'!D12*'参数设置'!E6+'月度收益'!E12*'参数设置'!E7)/C$30 -> -0.013302166 | D14: =('月度收益'!F12*'参数设置'!E8+'月度收益'!G12*'参数设置'!E9)/D$30 -> 0.0082727082 | E14: =('月度收益'!H12*'参数设置'!E10+'月度收益'!I12*'参数设置'!E11)/E$30 -> 0.0055410473 | F14: =('月度收益'!J12*'参数设置'!E12+'月度收益'!K12*'参数设置'!E13)/F$30 -> 0.010798259 | G14: =('月度收益'!L12*'参数设置'!E14+'月度收益'!M12*'参数设置'!E15)/G$30 -> 0.034273906 | H14: =SUMPRODUCT(B14:G14,$B$30:$G$30) -> 0.011142815
A15: 45688 | B15: =('月度收益'!B13*'参数设置'!E4+'月度收益'!C13*'参数设置'!E5)/B$30 -> -0.0063586101 | C15: =('月度收益'!D13*'参数设置'!E6+'月度收益'!E13*'参数设置'!E7)/C$30 -> -0.02906886 | D15: =('月度收益'!F13*'参数设置'!E8+'月度收益'!G13*'参数设置'!E9)/D$30 -> -0.026680696 | E15: =('月度收益'!H13*'参数设置'!E10+'月度收益'!I13*'参数设置'!E11)/E$30 -> -0.0026968918 | F15: =('月度收益'!J13*'参数设置'!E12+'月度收益'!K13*'参数设置'!E13)/F$30 -> -0.009549276 | G15: =('月度收益'!L13*'参数设置'!E14+'月度收益'!M13*'参数设置'!E15)/G$30 -> -0.0017735587 | H15: =SUMPRODUCT(B15:G15,$B$30:$G$30) -> -0.012866339
A16: 45716 | B16: =('月度收益'!B14*'参数设置'!E4+'月度收益'!C14*'参数设置'!E5)/B$30 -> -0.038634047 | C16: =('月度收益'!D14*'参数设置'!E6+'月度收益'!E14*'参数设置'!E7)/C$30 -> -0.016104269 | D16: =('月度收益'!F14*'参数设置'!E8+'月度收益'!G14*'参数设置'!E9)/D$30 -> -0.053606696 | E16: =('月度收益'!H14*'参数设置'!E10+'月度收益'!I14*'参数设置'!E11)/E$30 -> -0.011369876 | F16: =('月度收益'!J14*'参数设置'!E12+'月度收益'!K14*'参数设置'!E13)/F$30 -> 9.2175573e-05 | G16: =('月度收益'!L14*'参数设置'!E14+'月度收益'!M14*'参数设置'!E15)/G$30 -> -0.052295023 | H16: =SUMPRODUCT(B16:G16,$B$30:$G$30) -> -0.028579615
A17: 45747 | B17: =('月度收益'!B15*'参数设置'!E4+'月度收益'!C15*'参数设置'!E5)/B$30 -> -0.052567354 | C17: =('月度收益'!D15*'参数设置'!E6+'月度收益'!E15*'参数设置'!E7)/C$30 -> -0.027196287 | D17: =('月度收益'!F15*'参数设置'!E8+'月度收益'!G15*'参数设置'!E9)/D$30 -> -0.0039743103 | E17: =('月度收益'!H15*'参数设置'!E10+'月度收益'!I15*'参数设置'!E11)/E$30 -> -0.0026880521 | F17: =('月度收益'!J15*'参数设置'!E12+'月度收益'!K15*'参数设置'!E13)/F$30 -> -0.040873395 | G17: =('月度收益'!L15*'参数设置'!E14+'月度收益'!M15*'参数设置'!E15)/G$30 -> -0.040446128 | H17: =SUMPRODUCT(B17:G17,$B$30:$G$30) -> -0.028173916
A18: 45777 | B18: =('月度收益'!B16*'参数设置'!E4+'月度收益'!C16*'参数设置'!E5)/B$30 -> -0.076820776 | C18: =('月度收益'!D16*'参数设置'!E6+'月度收益'!E16*'参数设置'!E7)/C$30 -> -0.085921279 | D18: =('月度收益'!F16*'参数设置'!E8+'月度收益'!G16*'参数设置'!E9)/D$30 -> -0.085923686 | E18: =('月度收益'!H16*'参数设置'!E10+'月度收益'!I16*'参数设置'!E11)/E$30 -> -0.035192321 | F18: =('月度收益'!J16*'参数设置'!E12+'月度收益'!K16*'参数设置'!E13)/F$30 -> -0.045792742 | G18: =('月度收益'!L16*'参数设置'!E14+'月度收益'!M16*'参数设置'!E15)/G$30 -> -0.060333458 | H18: =SUMPRODUCT(B18:G18,$B$30:$G$30) -> -0.065711192
A19: 45808 | B19: =('月度收益'!B17*'参数设置'!E4+'月度收益'!C17*'参数设置'!E5)/B$30 -> 0.0074222586 | C19: =('月度收益'!D17*'参数设置'!E6+'月度收益'!E17*'参数设置'!E7)/C$30 -> 0.025005074 | D19: =('月度收益'!F17*'参数设置'!E8+'月度收益'!G17*'参数设置'!E9)/D$30 -> 0.033664574 | E19: =('月度收益'!H17*'参数设置'!E10+'月度收益'!I17*'参数设置'!E11)/E$30 -> 0.024970967 | F19: =('月度收益'!J17*'参数设置'!E12+'月度收益'!K17*'参数设置'!E13)/F$30 -> 0.014827501 | G19: =('月度收益'!L17*'参数设置'!E14+'月度收益'!M17*'参数设置'!E15)/G$30 -> 0.014285827 | H19: =SUMPRODUCT(B19:G19,$B$30:$G$30) -> 0.019909538
A20: 45838 | B20: =('月度收益'!B18*'参数设置'!E4+'月度收益'!C18*'参数设置'!E5)/B$30 -> 0.04966302 | C20: =('月度收益'!D18*'参数设置'!E6+'月度收益'!E18*'参数设置'!E7)/C$30 -> 0.074636966 | D20: =('月度收益'!F18*'参数设置'!E8+'月度收益'!G18*'参数设置'!E9)/D$30 -> 0.073012741 | E20: =('月度收益'!H18*'参数设置'!E10+'月度收益'!I18*'参数设置'!E11)/E$30 -> 0.033339849 | F20: =('月度收益'!J18*'参数设置'!E12+'月度收益'!K18*'参数设置'!E13)/F$30 -> 0.011533114 | G20: =('月度收益'!L18*'参数设置'!E14+'月度收益'!M18*'参数设置'!E15)/G$30 -> 0.013317024 | H20: =SUMPRODUCT(B20:G20,$B$30:$G$30) -> 0.043947961
A21: 45869 | B21: =('月度收益'!B19*'参数设置'!E4+'月度收益'!C19*'参数设置'!E5)/B$30 -> 0.055984618 | C21: =('月度收益'!D19*'参数设置'!E6+'月度收益'!E19*'参数设置'!E7)/C$30 -> 0.046818234 | D21: =('月度收益'!F19*'参数设置'!E8+'月度收益'!G19*'参数设置'!E9)/D$30 -> 0.028919128 | E21: =('月度收益'!H19*'参数设置'!E10+'月度收益'!I19*'参数设置'!E11)/E$30 -> 0.027659614 | F21: =('月度收益'!J19*'参数设置'!E12+'月度收益'!K19*'参数设置'!E13)/F$30 -> 0.048835322 | G21: =('月度收益'!L19*'参数设置'!E14+'月度收益'!M19*'参数设置'!E15)/G$30 -> 0.043670417 | H21: =SUMPRODUCT(B21:G21,$B$30:$G$30) -> 0.042269415
A22: 45900 | B22: =('月度收益'!B20*'参数设置'!E4+'月度收益'!C20*'参数设置'!E5)/B$30 -> 0.03685173 | C22: =('月度收益'!D20*'参数设置'!E6+'月度收益'!E20*'参数设置'!E7)/C$30 -> 0.01753169 | D22: =('月度收益'!F20*'参数设置'!E8+'月度收益'!G20*'参数设置'!E9)/D$30 -> 0.048362838 | E22: =('月度收益'!H20*'参数设置'!E10+'月度收益'!I20*'参数设置'!E11)/E$30 -> 0.012257314 | F22: =('月度收益'!J20*'参数设置'!E12+'月度收益'!K20*'参数设置'!E13)/F$30 -> -0.0017643462 | G22: =('月度收益'!L20*'参数设置'!E14+'月度收益'!M20*'参数设置'!E15)/G$30 -> 0.052623183 | H22: =SUMPRODUCT(B22:G22,$B$30:$G$30) -> 0.027608156
A23: 45930 | B23: =('月度收益'!B21*'参数设置'!E4+'月度收益'!C21*'参数设置'!E5)/B$30 -> 0.043403371 | C23: =('月度收益'!D21*'参数设置'!E6+'月度收益'!E21*'参数设置'!E7)/C$30 -> 0.067789921 | D23: =('月度收益'!F21*'参数设置'!E8+'月度收益'!G21*'参数设置'!E9)/D$30 -> 0.05758989 | E23: =('月度收益'!H21*'参数设置'!E10+'月度收益'!I21*'参数设置'!E11)/E$30 -> 0.03230804 | F23: =('月度收益'!J21*'参数设置'!E12+'月度收益'!K21*'参数设置'!E13)/F$30 -> 0.049245001 | G23: =('月度收益'!L21*'参数设置'!E14+'月度收益'!M21*'参数设置'!E15)/G$30 -> 0.066334284 | H23: =SUMPRODUCT(B23:G23,$B$30:$G$30) -> 0.052492468
A24: 45961 | B24: =('月度收益'!B22*'参数设置'!E4+'月度收益'!C22*'参数设置'!E5)/B$30 -> -0.0076071759 | C24: =('月度收益'!D22*'参数设置'!E6+'月度收益'!E22*'参数设置'!E7)/C$30 -> 0.012537962 | D24: =('月度收益'!F22*'参数设置'!E8+'月度收益'!G22*'参数设置'!E9)/D$30 -> -0.026223437 | E24: =('月度收益'!H22*'参数设置'!E10+'月度收益'!I22*'参数设置'!E11)/E$30 -> -0.01151469 | F24: =('月度收益'!J22*'参数设置'!E12+'月度收益'!K22*'参数设置'!E13)/F$30 -> 0.001611409 | G24: =('月度收益'!L22*'参数设置'!E14+'月度收益'!M22*'参数设置'!E15)/G$30 -> -0.0090818945 | H24: =SUMPRODUCT(B24:G24,$B$30:$G$30) -> -0.0064623503
A25: 45991 | B25: =('月度收益'!B23*'参数设置'!E4+'月度收益'!C23*'参数设置'!E5)/B$30 -> -0.0047643391 | C25: =('月度收益'!D23*'参数设置'!E6+'月度收益'!E23*'参数设置'!E7)/C$30 -> -0.01188912 | D25: =('月度收益'!F23*'参数设置'!E8+'月度收益'!G23*'参数设置'!E9)/D$30 -> -0.0077225655 | E25: =('月度收益'!H23*'参数设置'!E10+'月度收益'!I23*'参数设置'!E11)/E$30 -> -0.0080552459 | F25: =('月度收益'!J23*'参数设置'!E12+'月度收益'!K23*'参数设置'!E13)/F$30 -> -0.011049918 | G25: =('月度收益'!L23*'参数设置'!E14+'月度收益'!M23*'参数设置'!E15)/G$30 -> 0.012447227 | H25: =SUMPRODUCT(B25:G25,$B$30:$G$30) -> -0.0054406721
A26: 46022 | B26: =('月度收益'!B24*'参数设置'!E4+'月度收益'!C24*'参数设置'!E5)/B$30 -> 0.0072503004 | C26: =('月度收益'!D24*'参数设置'!E6+'月度收益'!E24*'参数设置'!E7)/C$30 -> -0.007061209 | D26: =('月度收益'!F24*'参数设置'!E8+'月度收益'!G24*'参数设置'!E9)/D$30 -> -0.0078375981 | E26: =('月度收益'!H24*'参数设置'!E10+'月度收益'!I24*'参数设置'!E11)/E$30 -> 0.0083727106 | F26: =('月度收益'!J24*'参数设置'!E12+'月度收益'!K24*'参数设置'!E13)/F$30 -> 0.023113259 | G26: =('月度收益'!L24*'参数设置'!E14+'月度收益'!M24*'参数设置'!E15)/G$30 -> 0.025408727 | H26: =SUMPRODUCT(B26:G26,$B$30:$G$30) -> 0.0075541824
A29: 行业 | B29: 科技 | C29: 金融 | D29: 医药 | E29: 消费 | F29: 能源 | G29: 工业
A30: 行业目标权重 | B30: =SUM('参数设置'!E4:E5) -> 0.19 | C30: =SUM('参数设置'!E6:E7) -> 0.18 | D30: =SUM('参数设置'!E8:E9) -> 0.16 | E30: =SUM('参数设置'!E10:E11) -> 0.17 | F30: =SUM('参数设置'!E12:E13) -> 0.15 | G30: =SUM('参数设置'!E14:E15) -> 0.15
A32: 样本协方差 | B32: 科技 | C32: 金融 | D32: 医药 | E32: 消费 | F32: 能源 | G32: 工业 | H32: Σw | I32: VaR贡献 | J32: 边际VaR | K32: 独立VaR
A33: 科技 | B33: =COVARIANCE.S(B$4:B$26,B$4:B$26) -> 0.0013524085 | C33: =COVARIANCE.S(B$4:B$26,C$4:C$26) -> 0.0011992657 | D33: =COVARIANCE.S(B$4:B$26,D$4:D$26) -> 0.0012559706 | E33: =COVARIANCE.S(B$4:B$26,E$4:E$26) -> 0.00067894933 | F33: =COVARIANCE.S(B$4:B$26,F$4:F$26) -> 0.0010365459 | G33: =COVARIANCE.S(B$4:B$26,G$4:G$26) -> 0.0014133312 | H33: =SUMPRODUCT(B33:G33,$B$30:$G$30) -> 0.0011566837 | I33: =B$30*H33*'参数设置'!$B$3*'参数设置'!$B$7/SQRT($B$41) -> 109321.76 | J33: =I33/B$30 -> 575377.7 | K33: =B$30*STDEV.S(B$4:B$26)*'参数设置'!$B$3*'参数设置'!$B$7 -> 114940.6
A34: 金融 | B34: =COVARIANCE.S(C$4:C$26,B$4:B$26) -> 0.0011992657 | C34: =COVARIANCE.S(C$4:C$26,C$4:C$26) -> 0.0014632107 | D34: =COVARIANCE.S(C$4:C$26,D$4:D$26) -> 0.0013546729 | E34: =COVARIANCE.S(C$4:C$26,E$4:E$26) -> 0.00072074452 | F34: =COVARIANCE.S(C$4:C$26,F$4:F$26) -> 0.0010089856 | G34: =COVARIANCE.S(C$4:C$26,G$4:G$26) -> 0.0011780811 | H34: =SUMPRODUCT(B34:G34,$B$30:$G$30) -> 0.0011585726 | I34: =C$30*H34*'参数设置'!$B$3*'参数设置'!$B$7/SQRT($B$41) -> 103737.12 | J34: =I34/C$30 -> 576317.34 | K34: =C$30*STDEV.S(C$4:C$26)*'参数设置'!$B$3*'参数设置'!$B$7 -> 113263.98
A35: 医药 | B35: =COVARIANCE.S(D$4:D$26,B$4:B$26) -> 0.0012559706 | C35: =COVARIANCE.S(D$4:D$26,C$4:C$26) -> 0.0013546729 | D35: =COVARIANCE.S(D$4:D$26,D$4:D$26) -> 0.0016739398 | E35: =COVARIANCE.S(D$4:D$26,E$4:E$26) -> 0.0008418844 | F35: =COVARIANCE.S(D$4:D$26,F$4:F$26) -> 0.00094224751 | G35: =COVARIANCE.S(D$4:D$26,G$4:G$26) -> 0.0014225041 | H35: =SUMPRODUCT(B35:G35,$B$30:$G$30) -> 0.001248139 | I35: =D$30*H35*'参数设置'!$B$3*'参数设置'!$B$7/SQRT($B$41) -> 99339.359 | J35: =I35/D$30 -> 620870.99 | K35: =D$30*STDEV.S(D$4:D$26)*'参数设置'!$B$3*'参数设置'!$B$7 -> 107685.15
A36: 消费 | B36: =COVARIANCE.S(E$4:E$26,B$4:B$26) -> 0.00067894933 | C36: =COVARIANCE.S(E$4:E$26,C$4:C$26) -> 0.00072074452 | D36: =COVARIANCE.S(E$4:E$26,D$4:D$26) -> 0.0008418844 | E36: =COVARIANCE.S(E$4:E$26,E$4:E$26) -> 0.00052812267 | F36: =COVARIANCE.S(E$4:E$26,F$4:F$26) -> 0.00069034729 | G36: =COVARIANCE.S(E$4:E$26,G$4:G$26) -> 0.00080748026 | H36: =SUMPRODUCT(B36:G36,$B$30:$G$30) -> 0.00070789088 | I36: =E$30*H36*'参数设置'!$B$3*'参数设置'!$B$7/SQRT($B$41) -> 59862.335 | J36: =I36/E$30 -> 352131.38 | K36: =E$30*STDEV.S(E$4:E$26)*'参数设置'!$B$3*'参数设置'!$B$7 -> 64266.142
A37: 能源 | B37: =COVARIANCE.S(F$4:F$26,B$4:B$26) -> 0.0010365459 | C37: =COVARIANCE.S(F$4:F$26,C$4:C$26) -> 0.0010089856 | D37: =COVARIANCE.S(F$4:F$26,D$4:D$26) -> 0.00094224751 | E37: =COVARIANCE.S(F$4:F$26,E$4:E$26) -> 0.00069034729 | F37: =COVARIANCE.S(F$4:F$26,F$4:F$26) -> 0.0011838957 | G37: =COVARIANCE.S(F$4:F$26,G$4:G$26) -> 0.0012238657 | H37: =SUMPRODUCT(B37:G37,$B$30:$G$30) -> 0.001007844 | I37: =F$30*H37*'参数设置'!$B$3*'参数设置'!$B$7/SQRT($B$41) -> 75200.891 | J37: =I37/F$30 -> 501339.27 | K37: =F$30*STDEV.S(F$4:F$26)*'参数设置'!$B$3*'参数设置'!$B$7 -> 84901.21
A38: 工业 | B38: =COVARIANCE.S(G$4:G$26,B$4:B$26) -> 0.0014133312 | C38: =COVARIANCE.S(G$4:G$26,C$4:C$26) -> 0.0011780811 | D38: =COVARIANCE.S(G$4:G$26,D$4:D$26) -> 0.0014225041 | E38: =COVARIANCE.S(G$4:G$26,E$4:E$26) -> 0.00080748026 | F38: =COVARIANCE.S(G$4:G$26,F$4:F$26) -> 0.0012238657 | G38: =COVARIANCE.S(G$4:G$26,G$4:G$26) -> 0.0017645285 | H38: =SUMPRODUCT(B38:G38,$B$30:$G$30) -> 0.001293719 | I38: =G$30*H38*'参数设置'!$B$3*'参数设置'!$B$7/SQRT($B$41) -> 96531.626 | J38: =I38/G$30 -> 643544.17 | K38: =G$30*STDEV.S(G$4:G$26)*'参数设置'!$B$3*'参数设置'!$B$7 -> 103650.52
A41: 组合月方差 | B41: =B30*H33+C30*H34+D30*H35+E30*H36+F30*H37+G30*H38 -> 0.0010935911
A42: 协方差组合VaR | B42: =SQRT(B41)*'参数设置'!B3*'参数设置'!B7 -> 543993.09
A43: 贡献合计 | B43: =SUM(I33:I38) -> 543993.09
A44: 分散化收益 | B44: =SUM(K33:K38)-B42 -> 44714.507
A45: 最大风险贡献行业 | B45: =INDEX(A33:A38,MATCH(MAX(I33:I38),I33:I38,0)) -> 科技

Sheet 风险回测
A1: 单步前瞻风险回测（前12个月预测下一月）
A3: 检验月末 | B3: 实际组合月收益 | C3: 前12月年化波动 | D3: 前12月Beta | E3: 前12月跟踪误差 | F3: 90%历史VaR率 | G3: 90%历史ES率 | H3: VaR突破 | I3: 前12月信息比率 | J3: 实际损失率 | N3: 月末 | O3: 主动月收益
A4: 45716 | B4: ='月度收益'!O14 -> -0.028579615 | C4: =STDEV.S('月度收益'!O2:O13)*SQRT(12) -> 0.10483841 | D4: =SLOPE('月度收益'!O2:O13,'月度收益'!N2:N13) -> 1.0159465 | E4: =STDEV.S($O$4:$O$15)*SQRT(12) -> 0.0064984502 | F4: =MAX(0,-SMALL('月度收益'!O2:O13,2)) -> 0.012866339 | G4: =MAX(0,-AVERAGE(SMALL('月度收益'!O2:O13,1),SMALL('月度收益'!O2:O13,2))) -> 0.02610491 | H4: =IF(B4<-F4,1,0) -> 1 | I4: =AVERAGE($O$4:$O$15)*12/E4 -> 9.2646316 | J4: =MAX(0,-B4) -> 0.028579615 | N4: 45351 | O4: ='月度收益'!O2-'月度收益'!N2 -> 0.0078243273
A5: 45747 | B5: ='月度收益'!O15 -> -0.028173916 | C5: =STDEV.S('月度收益'!O3:O14)*SQRT(12) -> 0.11065526 | D5: =SLOPE('月度收益'!O3:O14,'月度收益'!N3:N14) -> 1.0160922 | E5: =STDEV.S($O$5:$O$16)*SQRT(12) -> 0.0060911758 | F5: =MAX(0,-SMALL('月度收益'!O3:O14,2)) -> 0.028579615 | G5: =MAX(0,-AVERAGE(SMALL('月度收益'!O3:O14,1),SMALL('月度收益'!O3:O14,2))) -> 0.033961548 | H5: =IF(B5<-F5,1,0) -> 0 | I5: =AVERAGE($O$5:$O$16)*12/E5 -> 9.0428576 | J5: =MAX(0,-B5) -> 0.028173916 | N5: 45382 | O5: ='月度收益'!O3-'月度收益'!N3 -> 0.0046996848
A6: 45777 | B6: ='月度收益'!O16 -> -0.065711192 | C6: =STDEV.S('月度收益'!O4:O15)*SQRT(12) -> 0.1142269 | D6: =SLOPE('月度收益'!O4:O15,'月度收益'!N4:N15) -> 1.0285783 | E6: =STDEV.S($O$6:$O$17)*SQRT(12) -> 0.0080196058 | F6: =MAX(0,-SMALL('月度收益'!O4:O15,2)) -> 0.028579615 | G6: =MAX(0,-AVERAGE(SMALL('月度收益'!O4:O15,1),SMALL('月度收益'!O4:O15,2))) -> 0.033961548 | H6: =IF(B6<-F6,1,0) -> 1 | I6: =AVERAGE($O$6:$O$17)*12/E6 -> 6.2028335 | J6: =MAX(0,-B6) -> 0.065711192 | N6: 45412 | O6: ='月度收益'!O4-'月度收益'!N4 -> 0.0022071911
A7: 45808 | B7: ='月度收益'!O17 -> 0.019909538 | C7: =STDEV.S('月度收益'!O5:O16)*SQRT(12) -> 0.13363805 | D7: =SLOPE('月度收益'!O5:O16,'月度收益'!N5:N16) -> 1.0467309 | E7: =STDEV.S($O$7:$O$18)*SQRT(12) -> 0.0097544413 | F7: =MAX(0,-SMALL('月度收益'!O5:O16,2)) -> 0.039343481 | G7: =MAX(0,-AVERAGE(SMALL('月度收益'!O5:O16,1),SMALL('月度收益'!O5:O16,2))) -> 0.052527337 | H7: =IF(B7<-F7,1,0) -> 0 | I7: =AVERAGE($O$7:$O$18)*12/E7 -> 4.7072704 | J7: =MAX(0,-B7) -> 0 | N7: 45443 | O7: ='月度收益'!O5-'月度收益'!N5 -> 0.0015677445
A8: 45838 | B8: ='月度收益'!O18 -> 0.043947961 | C8: =STDEV.S('月度收益'!O6:O17)*SQRT(12) -> 0.13532638 | D8: =SLOPE('月度收益'!O6:O17,'月度收益'!N6:N17) -> 1.0476691 | E8: =STDEV.S($O$8:$O$19)*SQRT(12) -> 0.0095416578 | F8: =MAX(0,-SMALL('月度收益'!O6:O17,2)) -> 0.039343481 | G8: =MAX(0,-AVERAGE(SMALL('月度收益'!O6:O17,1),SMALL('月度收益'!O6:O17,2))) -> 0.052527337 | H8: =IF(B8<-F8,1,0) -> 0 | I8: =AVERAGE($O$8:$O$19)*12/E8 -> 5.2174043 | J8: =MAX(0,-B8) -> 0 | N8: 45473 | O8: ='月度收益'!O6-'月度收益'!N6 -> 0.0071524212
A9: 45869 | B9: ='月度收益'!O19 -> 0.042269415 | C9: =STDEV.S('月度收益'!O7:O18)*SQRT(12) -> 0.14201885 | D9: =SLOPE('月度收益'!O7:O18,'月度收益'!N7:N18) -> 1.0630019 | E9: =STDEV.S($O$9:$O$20)*SQRT(12) -> 0.012564155 | F9: =MAX(0,-SMALL('月度收益'!O7:O18,2)) -> 0.039343481 | G9: =MAX(0,-AVERAGE(SMALL('月度收益'!O7:O18,1),SMALL('月度收益'!O7:O18,2))) -> 0.052527337 | H9: =IF(B9<-F9,1,0) -> 0 | I9: =AVERAGE($O$9:$O$20)*12/E9 -> 4.4023786 | J9: =MAX(0,-B9) -> 0 | N9: 45504 | O9: ='月度收益'!O7-'月度收益'!N7 -> 0.004631371
